<?xml version="1.0" ?>
<robot name="complete_newhands">
	<link name="torso:11">
		<visual>
			<geometry>
				<mesh filename="package://iris_sandbox//2016_04_13_NICO/torso_iam_fb80b350.STL" scale="0.001 0.001 0.001"/>
			</geometry>
			<origin rpy="0 0 0" xyz="-0.026368 -0.075212 0.525308"/>
			<material name="torso:11_color">
				<color rgba="0.270588 0.270588 0.270588 1"/>
			</material>
		</visual>
		<collision>
			<geometry>
				<mesh filename="package://iris_sandbox//2016_04_13_NICO/torso_iam_fb80b350.STL" scale="0.001 0.001 0.001"/>
			</geometry>
			<origin rpy="0 0 0" xyz="-0.026368 -0.075212 0.525308"/>
		</collision>
		<inertial>
			<mass value="0.607828"/>
			<inertia ixx="0.006338" ixy="0.000004" ixz="0.000248" iyy="0.005208" iyz="0.000001" izz="0.002162"/>
			<origin rpy="0 0 0" xyz="0.01632 -0.000121 0.649656"/>
		</inertial>
	</link>
	<link name="neck:11">
		<visual>
			<geometry>
				<mesh filename="package://iris_sandbox//2016_04_13_NICO/neck_iam_61141f4f.STL" scale="0.001 0.001 0.001"/>
			</geometry>
			<origin rpy="0 0 0" xyz="-0.015583 -0.0205 0"/>
			<material name="neck:11_color">
				<color rgba="0.74902 0.74902 0.74902 1"/>
			</material>
		</visual>
		<collision>
			<geometry>
				<mesh filename="package://iris_sandbox//2016_04_13_NICO/neck_iam_61141f4f.STL" scale="0.001 0.001 0.001"/>
			</geometry>
			<origin rpy="0 0 0" xyz="-0.015583 -0.0205 0"/>
		</collision>
		<inertial>
			<mass value="0.090439"/>
			<inertia ixx="0.00006" ixy="-0" ixz="-0" iyy="0.000056" iyz="-0.000001" izz="0.000019"/>
			<origin rpy="0 0 0" xyz="0 0.000266 0.050352"/>
		</inertial>
	</link>
	<joint name="neck:1--torso:11" type="continuous">
		<parent link="torso:11"/>
		<child link="neck:11"/>
		<origin rpy="0 0 0" xyz="0.001283 -0.000212 0.756309"/>
		<axis xyz="0 0 1"/>
	</joint>
	<link name="head:21">
		<visual>
			<geometry>
				<mesh filename="package://iris_sandbox//2016_04_13_NICO/head_iam_b9cf2ea.STL" scale="0.001 0.001 0.001"/>
			</geometry>
			<origin rpy="0 0 0" xyz="-0.003998 -0.016462 0.04478"/>
			<material name="head:21_color">
				<color rgba="0.74902 0.74902 0.74902 1"/>
			</material>
		</visual>
		<collision>
			<geometry>
				<mesh filename="package://iris_sandbox//2016_04_13_NICO/head_iam_b9cf2ea.STL" scale="0.001 0.001 0.001"/>
			</geometry>
			<origin rpy="0 0 0" xyz="-0.003998 -0.016462 0.04478"/>
		</collision>
		<inertial>
			<mass value="0.294137"/>
			<inertia ixx="0.001424" ixy="-0" ixz="0.000083" iyy="0.00159" iyz="-0.000002" izz="0.001485"/>
			<origin rpy="0 0 0" xyz="0.01525 -0.023771 0.09423"/>
		</inertial>
	</link>
	<joint name="neck:1--head:21" type="continuous">
		<parent link="neck:11"/>
		<child link="head:21"/>
		<origin rpy="0 0 0" xyz="0 0.023001 0.0745"/>
		<axis xyz="0 -1 0"/>
	</joint>
	<link name="left_shoulder:11">
		<visual>
			<geometry>
				<mesh filename="package://iris_sandbox//2016_04_13_NICO/left_shoulder_up_iam_1ca4d925.STL" scale="0.001 0.001 0.001"/>
			</geometry>
			<origin rpy="0 0 0" xyz="0.014919 0.097299 -0.01461"/>
			<material name="left_shoulder:11_color">
				<color rgba="0.176471 0.176471 0.176471 1"/>
			</material>
		</visual>
		<collision>
			<geometry>
				<mesh filename="package://iris_sandbox//2016_04_13_NICO/left_shoulder_up_iam_1ca4d925.STL" scale="0.001 0.001 0.001"/>
			</geometry>
			<origin rpy="0 0 0" xyz="0.014919 0.097299 -0.01461"/>
		</collision>
		<inertial>
			<mass value="0.084038"/>
			<inertia ixx="0.000026" ixy="-0.000001" ixz="-0.000002" iyy="0.000034" iyz="-0" izz="0.000033"/>
			<origin rpy="0 0 0" xyz="0.005702 0.000175 0.033153"/>
		</inertial>
	</link>
	<joint name="left_shoulder:1--torso:11" type="continuous">
		<parent link="torso:11"/>
		<child link="left_shoulder:11"/>
		<origin rpy="0 0 0.019538" xyz="0.026783 0.049488 0.748809"/>
		<axis xyz="0 0 1"/>
	</joint>
	<link name="left_collarbone:11">
		<visual>
			<geometry>
				<mesh filename="package://iris_sandbox//2016_04_13_NICO/left_upper_arm_iam_49d50008.STL" scale="0.001 0.001 0.001"/>
			</geometry>
			<origin rpy="0 0 0" xyz="-0.000321 -0.000277 0.000298"/>
			<material name="left_collarbone:11_color">
				<color rgba="0.176471 0.176471 0.176471 1"/>
			</material>
		</visual>
		<collision>
			<geometry>
				<mesh filename="package://iris_sandbox//2016_04_13_NICO/left_upper_arm_iam_49d50008.STL" scale="0.001 0.001 0.001"/>
			</geometry>
			<origin rpy="0 0 0" xyz="-0.000321 -0.000277 0.000298"/>
		</collision>
		<inertial>
			<mass value="0.024811"/>
			<inertia ixx="0.000014" ixy="0" ixz="0" iyy="0.000011" iyz="0.000001" izz="0.000019"/>
			<origin rpy="0 0 0" xyz="-0 0.041345 -0.002364"/>
		</inertial>
	</link>
	<joint name="left_collarbone:1--left_shoulder:11" type="continuous">
		<parent link="left_shoulder:11"/>
		<child link="left_collarbone:11"/>
		<origin rpy="0 0 -0.019538" xyz="0.022445 0.022567 0.037"/>
		<axis xyz="0 -1 0"/>
	</joint>
	<link name="left_upper_arm:11">
		<visual>
			<geometry>
				<mesh filename="package://iris_sandbox//2016_04_13_NICO/left_lower_arm_iam_5be2a521.STL" scale="0.001 0.001 0.001"/>
			</geometry>
			<origin rpy="0 0 0" xyz="-0.044837 -0.00935 -0.161585"/>
			<material name="left_upper_arm:11_color">
				<color rgba="0.176471 0.176471 0.176471 1"/>
			</material>
		</visual>
		<collision>
			<geometry>
				<mesh filename="package://iris_sandbox//2016_04_13_NICO/left_lower_arm_iam_5be2a521.STL" scale="0.001 0.001 0.001"/>
			</geometry>
			<origin rpy="0 0 0" xyz="-0.044837 -0.00935 -0.161585"/>
		</collision>
		<inertial>
			<mass value="0.192388"/>
			<inertia ixx="0.00085" ixy="0" ixz="-0.00005" iyy="0.000853" iyz="0.000001" izz="0.000052"/>
			<origin rpy="0 0 0" xyz="-0.028636 -0.000703 -0.084225"/>
		</inertial>
	</link>
	<joint name="left_upper_arm:1--left_collarbone:11" type="continuous">
		<parent link="left_collarbone:11"/>
		<child link="left_upper_arm:11"/>
		<origin rpy="0 -0.051282 0" xyz="0.0245 0.073664 -0.022853"/>
		<axis xyz="1 0 0"/>
	</joint>
	<link name="left_lower_arm:11">
		<visual>
			<geometry>
				<mesh filename="package://iris_sandbox//2016_04_13_NICO/right_wrist_MIR_iam_dcfe6de3.STL" scale="0.001 0.001 0.001"/>
			</geometry>
			<origin rpy="0 0 0" xyz="0.000017 -0.010775 -0.12546"/>
			<material name="left_lower_arm:11_color">
				<color rgba="0.176471 0.176471 0.176471 1"/>
			</material>
		</visual>
		<collision>
			<geometry>
				<mesh filename="package://iris_sandbox//2016_04_13_NICO/right_wrist_MIR_iam_dcfe6de3.STL" scale="0.001 0.001 0.001"/>
			</geometry>
			<origin rpy="0 0 0" xyz="0.000017 -0.010775 -0.12546"/>
		</collision>
		<inertial>
			<mass value="0.076791"/>
			<inertia ixx="0.000104" ixy="-0" ixz="-0" iyy="0.000095" iyz="0.000002" izz="0.000021"/>
			<origin rpy="0 0 0" xyz="0 -0.022485 -0.081055"/>
		</inertial>
	</link>
	<joint name="left_lower_arm:1--left_upper_arm:11" type="continuous">
		<parent link="left_upper_arm:11"/>
		<child link="left_lower_arm:11"/>
		<origin rpy="0 0.097508 0" xyz="-0.034583 0.023065 -0.16986"/>
		<axis xyz="0 1 0"/>
	</joint>
	<link name="left_hip_up_MIR:11">
		<visual>
			<geometry>
				<mesh filename="package://iris_sandbox//2016_04_13_NICO/right_hip_up_MIR_iam_386ac7b2.STL" scale="0.001 0.001 0.001"/>
			</geometry>
			<origin rpy="0 0 0" xyz="-0.05 -0.018 -0.0007"/>
			<material name="left_hip_up_MIR:11_color">
				<color rgba="0.176471 0.176471 0.176471 1"/>
			</material>
		</visual>
		<collision>
			<geometry>
				<mesh filename="package://iris_sandbox//2016_04_13_NICO/right_hip_up_MIR_iam_386ac7b2.STL" scale="0.001 0.001 0.001"/>
			</geometry>
			<origin rpy="0 0 0" xyz="-0.05 -0.018 -0.0007"/>
		</collision>
		<inertial>
			<mass value="0.072012"/>
			<inertia ixx="0.000028" ixy="0" ixz="0.00001" iyy="0.000117" iyz="-0" izz="0.000108"/>
			<origin rpy="0 0 0" xyz="0.005067 -0.000001 -0.012736"/>
		</inertial>
	</link>
	<joint name="left_hip_up_MIR:1--torso:11" type="continuous">
		<parent link="torso:11"/>
		<child link="left_hip_up_MIR:11"/>
		<origin rpy="0 0 0" xyz="0.010783 0.054788 0.519208"/>
		<axis xyz="0 0 -1"/>
	</joint>
	<link name="left_hip_low_MIR:11">
		<visual>
			<geometry>
				<mesh filename="package://iris_sandbox//2016_04_13_NICO/right_hip_up2_MIR_iam_b8a74a0a.STL" scale="0.001 0.001 0.001"/>
			</geometry>
			<origin rpy="0 0 0" xyz="0.0031 -0.023 -0.025201"/>
			<material name="left_hip_low_MIR:11_color">
				<color rgba="0.176471 0.176471 0.176471 1"/>
			</material>
		</visual>
		<collision>
			<geometry>
				<mesh filename="package://iris_sandbox//2016_04_13_NICO/right_hip_up2_MIR_iam_b8a74a0a.STL" scale="0.001 0.001 0.001"/>
			</geometry>
			<origin rpy="0 0 0" xyz="0.0031 -0.023 -0.025201"/>
		</collision>
		<inertial>
			<mass value="0.17834"/>
			<inertia ixx="0.000077" ixy="-0.000001" ixz="0.000001" iyy="0.000157" iyz="-0.000001" izz="0.00013"/>
			<origin rpy="0 0 0" xyz="0.04747 0.00023 -0.015465"/>
		</inertial>
	</link>
	<joint name="left_hip_low_MIR:1--left_hip_up_MIR:11" type="continuous">
		<parent link="left_hip_up_MIR:11"/>
		<child link="left_hip_low_MIR:11"/>
		<origin rpy="0 0 0" xyz="-0.046 0 -0.0414"/>
		<axis xyz="-1 0 0"/>
	</joint>
	<link name="left_thigh:11">
		<visual>
			<geometry>
				<mesh filename="package://iris_sandbox//2016_04_13_NICO/thigh_left_complete_iam_5a6ba909.STL" scale="0.001 0.001 0.001"/>
			</geometry>
			<origin rpy="0 0 0" xyz="-0.04583 -0.056 -0.100647"/>
			<material name="left_thigh:11_color">
				<color rgba="0.176471 0.176471 0.176471 1"/>
			</material>
		</visual>
		<collision>
			<geometry>
				<mesh filename="package://iris_sandbox//2016_04_13_NICO/thigh_left_complete_iam_5a6ba909.STL" scale="0.001 0.001 0.001"/>
			</geometry>
			<origin rpy="0 0 0" xyz="-0.04583 -0.056 -0.100647"/>
		</collision>
		<inertial>
			<mass value="0.177251"/>
			<inertia ixx="0.000918" ixy="0.000001" ixz="-0.000093" iyy="0.000883" iyz="0.000003" izz="0.000125"/>
			<origin rpy="0 0 0" xyz="-0.029925 -0.02577 -0.151365"/>
		</inertial>
	</link>
	<joint name="left_thigh:1--left_hip_low_MIR:11" type="continuous">
		<parent link="left_hip_low_MIR:11"/>
		<child link="left_thigh:11"/>
		<origin rpy="0 0.018214 0" xyz="0.0692 0.0261 0"/>
		<axis xyz="0 -1 0"/>
	</joint>
	<link name="left_shank_MIR:11">
		<visual>
			<geometry>
				<mesh filename="package://iris_sandbox//2016_04_13_NICO/right_shank_MIR_iam_a2a9b5d0.STL" scale="0.001 0.001 0.001"/>
			</geometry>
			<origin rpy="0 0 0" xyz="-0.004901 -0.056 -0.03453"/>
			<material name="left_shank_MIR:11_color">
				<color rgba="0.176471 0.176471 0.176471 1"/>
			</material>
		</visual>
		<collision>
			<geometry>
				<mesh filename="package://iris_sandbox//2016_04_13_NICO/right_shank_MIR_iam_a2a9b5d0.STL" scale="0.001 0.001 0.001"/>
			</geometry>
			<origin rpy="0 0 0" xyz="-0.004901 -0.056 -0.03453"/>
		</collision>
		<inertial>
			<mass value="0.084704"/>
			<inertia ixx="0.000448" ixy="0" ixz="0.000025" iyy="0.000404" iyz="0" izz="0.000078"/>
			<origin rpy="0 0 0" xyz="0.015999 -0.026 -0.104866"/>
		</inertial>
	</link>
	<joint name="left_shank_MIR:1--left_thigh:11" type="continuous">
		<parent link="left_thigh:11"/>
		<child link="left_shank_MIR:11"/>
		<origin rpy="0 -0.019054 0" xyz="-0.048258 0.0018 -0.214642"/>
		<axis xyz="0 1 0"/>
	</joint>
	<link name="left_ankle_MIR:11">
		<visual>
			<geometry>
				<mesh filename="package://iris_sandbox//2016_04_13_NICO/right_ankle_MIR_iam_c5a384f4.STL" scale="0.001 0.001 0.001"/>
			</geometry>
			<origin rpy="0 0 0" xyz="-0.0661 -0.0491 0.025201"/>
			<material name="left_ankle_MIR:11_color">
				<color rgba="0.176471 0.176471 0.176471 1"/>
			</material>
		</visual>
		<collision>
			<geometry>
				<mesh filename="package://iris_sandbox//2016_04_13_NICO/right_ankle_MIR_iam_c5a384f4.STL" scale="0.001 0.001 0.001"/>
			</geometry>
			<origin rpy="0 0 0" xyz="-0.0661 -0.0491 0.025201"/>
		</collision>
		<inertial>
			<mass value="0.179549"/>
			<inertia ixx="0.000078" ixy="-0" ixz="-0.000001" iyy="0.000158" iyz="0.000001" izz="0.000132"/>
			<origin rpy="0 0 0" xyz="-0.021584 -0.026039 0.015361"/>
		</inertial>
	</link>
	<joint name="left_ankle_MIR:1--left_shank_MIR:11" type="continuous">
		<parent link="left_shank_MIR:11"/>
		<child link="left_ankle_MIR:11"/>
		<origin rpy="0 0.00084 0" xyz="0.03924 0 -0.216473"/>
		<axis xyz="0 1 0"/>
	</joint>
	<link name="left_foot:11">
		<visual>
			<geometry>
				<mesh filename="package://iris_sandbox//2016_04_13_NICO/left_foot_iam_620666ef.STL" scale="0.001 0.001 0.001"/>
			</geometry>
			<origin rpy="0 0 0" xyz="-0.004 -0.024 -0.033621"/>
			<material name="left_foot:11_color">
				<color rgba="0.176471 0.176471 0.176471 1"/>
			</material>
		</visual>
		<collision>
			<geometry>
				<mesh filename="package://iris_sandbox//2016_04_13_NICO/left_foot_iam_620666ef.STL" scale="0.001 0.001 0.001"/>
			</geometry>
			<origin rpy="0 0 0" xyz="-0.004 -0.024 -0.033621"/>
		</collision>
		<inertial>
			<mass value="0.072801"/>
			<inertia ixx="0.000097" ixy="-0.000003" ixz="-0.000001" iyy="0.000283" iyz="0.000003" izz="0.000362"/>
			<origin rpy="0 0 0" xyz="0.074087 0.008929 -0.031819"/>
		</inertial>
	</link>
	<joint name="left_foot:1--left_ankle_MIR:11" type="continuous">
		<parent link="left_ankle_MIR:11"/>
		<child link="left_foot:11"/>
		<origin rpy="0 0 0" xyz="-0.0709 -0.0261 0"/>
		<axis xyz="-1 0 0"/>
	</joint>
	<link name="right_hip_up:11">
		<visual>
			<geometry>
				<mesh filename="package://iris_sandbox//2016_04_13_NICO/right_hip_up_iam_f46f7684.STL" scale="0.001 0.001 0.001"/>
			</geometry>
			<origin rpy="0 0 0" xyz="-0.05 -0.018 -0.002769"/>
			<material name="right_hip_up:11_color">
				<color rgba="0.176471 0.176471 0.176471 1"/>
			</material>
		</visual>
		<collision>
			<geometry>
				<mesh filename="package://iris_sandbox//2016_04_13_NICO/right_hip_up_iam_f46f7684.STL" scale="0.001 0.001 0.001"/>
			</geometry>
			<origin rpy="0 0 0" xyz="-0.05 -0.018 -0.002769"/>
		</collision>
		<inertial>
			<mass value="0.026572"/>
			<inertia ixx="0.00001" ixy="-0" ixz="0.000004" iyy="0.000043" iyz="0" izz="0.00004"/>
			<origin rpy="0 0 0" xyz="0.005067 0.00002 -0.012737"/>
		</inertial>
	</link>
	<joint name="right_hip_up:1--torso:11" type="continuous">
		<parent link="torso:11"/>
		<child link="right_hip_up:11"/>
		<origin rpy="0 0 0" xyz="0.010783 -0.055212 0.519208"/>
		<axis xyz="0 0 1"/>
	</joint>
	<link name="right_hip_low:11">
		<visual>
			<geometry>
				<mesh filename="package://iris_sandbox//2016_04_13_NICO/right_hip_up2_iam_f4f7d16a.STL" scale="0.001 0.001 0.001"/>
			</geometry>
			<origin rpy="0 0 0" xyz="0.0031 -0.023 -0.025201"/>
			<material name="right_hip_low:11_color">
				<color rgba="0.176471 0.176471 0.176471 1"/>
			</material>
		</visual>
		<collision>
			<geometry>
				<mesh filename="package://iris_sandbox//2016_04_13_NICO/right_hip_up2_iam_f4f7d16a.STL" scale="0.001 0.001 0.001"/>
			</geometry>
			<origin rpy="0 0 0" xyz="0.0031 -0.023 -0.025201"/>
		</collision>
		<inertial>
			<mass value="0.178341"/>
			<inertia ixx="0.000077" ixy="-0.000001" ixz="0.000001" iyy="0.000157" iyz="-0.000001" izz="0.00013"/>
			<origin rpy="0 0 0" xyz="0.04747 0.000227 -0.015465"/>
		</inertial>
	</link>
	<joint name="right_hip_low:1--right_hip_up:11" type="continuous">
		<parent link="right_hip_up:11"/>
		<child link="right_hip_low:11"/>
		<origin rpy="0.000512 0 0" xyz="-0.046 0 -0.0414"/>
		<axis xyz="1 0 0"/>
	</joint>
	<link name="right_thigh:11">
		<visual>
			<geometry>
				<mesh filename="package://iris_sandbox//2016_04_13_NICO/thigh_right_complete_iam_6502f197.STL" scale="0.001 0.001 0.001"/>
			</geometry>
			<origin rpy="0 0 0" xyz="-0.04583 -0.056 -0.070383"/>
			<material name="right_thigh:11_color">
				<color rgba="0.176471 0.176471 0.176471 1"/>
			</material>
		</visual>
		<collision>
			<geometry>
				<mesh filename="package://iris_sandbox//2016_04_13_NICO/thigh_right_complete_iam_6502f197.STL" scale="0.001 0.001 0.001"/>
			</geometry>
			<origin rpy="0 0 0" xyz="-0.04583 -0.056 -0.070383"/>
		</collision>
		<inertial>
			<mass value="0.177251"/>
			<inertia ixx="0.000918" ixy="0.000001" ixz="-0.000093" iyy="0.000883" iyz="0.000003" izz="0.000125"/>
			<origin rpy="0 0 0" xyz="-0.029925 -0.02577 -0.151364"/>
		</inertial>
	</link>
	<joint name="right_thigh:1--right_hip_low:11" type="continuous">
		<parent link="right_hip_low:11"/>
		<child link="right_thigh:11"/>
		<origin rpy="0 0.017985 0" xyz="0.0692 0.0261 -0"/>
		<axis xyz="0 -1 -0.000511678"/>
	</joint>
	<link name="right_shank:11">
		<visual>
			<geometry>
				<mesh filename="package://iris_sandbox//2016_04_13_NICO/right_shank_iam_7a73fe91.STL" scale="0.001 0.001 0.001"/>
			</geometry>
			<origin rpy="0 0 0" xyz="-0.004901 -0.056 -0.081799"/>
			<material name="right_shank:11_color">
				<color rgba="0.176471 0.176471 0.176471 1"/>
			</material>
		</visual>
		<collision>
			<geometry>
				<mesh filename="package://iris_sandbox//2016_04_13_NICO/right_shank_iam_7a73fe91.STL" scale="0.001 0.001 0.001"/>
			</geometry>
			<origin rpy="0 0 0" xyz="-0.004901 -0.056 -0.081799"/>
		</collision>
		<inertial>
			<mass value="0.084704"/>
			<inertia ixx="0.000448" ixy="0" ixz="0.000025" iyy="0.000404" iyz="0" izz="0.000078"/>
			<origin rpy="0 0 0" xyz="0.015999 -0.026 -0.104866"/>
		</inertial>
	</link>
	<joint name="right_shank:1--right_thigh:11" type="continuous">
		<parent link="right_thigh:11"/>
		<child link="right_shank:11"/>
		<origin rpy="0 -0.017619 0" xyz="-0.048258 0.0001 -0.214642"/>
		<axis xyz="0 1 0.000511678"/>
	</joint>
	<link name="right_ankle:11">
		<visual>
			<geometry>
				<mesh filename="package://iris_sandbox//2016_04_13_NICO/right_ankle_iam_f4f7d16a.STL" scale="0.001 0.001 0.001"/>
			</geometry>
			<origin rpy="0 0 0" xyz="-0.0661 0.0031 -0.011201"/>
			<material name="right_ankle:11_color">
				<color rgba="0.176471 0.176471 0.176471 1"/>
			</material>
		</visual>
		<collision>
			<geometry>
				<mesh filename="package://iris_sandbox//2016_04_13_NICO/right_ankle_iam_f4f7d16a.STL" scale="0.001 0.001 0.001"/>
			</geometry>
			<origin rpy="0 0 0" xyz="-0.0661 0.0031 -0.011201"/>
		</collision>
		<inertial>
			<mass value="0.178341"/>
			<inertia ixx="0.000077" ixy="0.000001" ixz="-0.000001" iyy="0.000157" iyz="-0.000001" izz="0.00013"/>
			<origin rpy="0 0 0" xyz="-0.02173 0.025873 0.015465"/>
		</inertial>
	</link>
	<joint name="right_ankle:1--right_shank:11" type="continuous">
		<parent link="right_shank:11"/>
		<child link="right_ankle:11"/>
		<origin rpy="0 -0.000292 0" xyz="0.03924 -0.052 -0.216472"/>
		<axis xyz="0 1 0.000511678"/>
	</joint>
	<link name="right_foot:11">
		<visual>
			<geometry>
				<mesh filename="package://iris_sandbox//2016_04_13_NICO/right_foot_iam_3ff7356a.STL" scale="0.001 0.001 0.001"/>
			</geometry>
			<origin rpy="0 0 0" xyz="-0.004 -0.024 -0.009365"/>
			<material name="right_foot:11_color">
				<color rgba="0.176471 0.176471 0.176471 1"/>
			</material>
		</visual>
		<collision>
			<geometry>
				<mesh filename="package://iris_sandbox//2016_04_13_NICO/right_foot_iam_3ff7356a.STL" scale="0.001 0.001 0.001"/>
			</geometry>
			<origin rpy="0 0 0" xyz="-0.004 -0.024 -0.009365"/>
		</collision>
		<inertial>
			<mass value="0.072801"/>
			<inertia ixx="0.000097" ixy="0.000003" ixz="-0.000001" iyy="0.000283" iyz="-0.000003" izz="0.000362"/>
			<origin rpy="0 0 0" xyz="0.074125 -0.00893 -0.031819"/>
		</inertial>
	</link>
	<joint name="right_foot:1--right_ankle:11" type="continuous">
		<parent link="right_ankle:11"/>
		<child link="right_foot:11"/>
		<origin rpy="-0.014983 0 0" xyz="-0.0709 0.0261 0"/>
		<axis xyz="-1 -3.80407e-008 7.43451e-005"/>
	</joint>
	<link name="right_shoulder:11">
		<visual>
			<geometry>
				<mesh filename="package://iris_sandbox//2016_04_13_NICO/right_shoulder_up_iam_34db21c8.STL" scale="0.001 0.001 0.001"/>
			</geometry>
			<origin rpy="0 0 0" xyz="-0.062271 0.032843 -0.74045"/>
			<material name="right_shoulder:11_color">
				<color rgba="0.176471 0.176471 0.176471 1"/>
			</material>
		</visual>
		<collision>
			<geometry>
				<mesh filename="package://iris_sandbox//2016_04_13_NICO/right_shoulder_up_iam_34db21c8.STL" scale="0.001 0.001 0.001"/>
			</geometry>
			<origin rpy="0 0 0" xyz="-0.062271 0.032843 -0.74045"/>
		</collision>
		<inertial>
			<mass value="0.084038"/>
			<inertia ixx="0.000026" ixy="-0.000001" ixz="-0.000002" iyy="0.000034" iyz="-0" izz="0.000033"/>
			<origin rpy="0 0 0" xyz="0.005637 0.000876 0.033153"/>
		</inertial>
	</link>
	<joint name="right_shoulder:1--torso:11" type="continuous">
		<parent link="torso:11"/>
		<child link="right_shoulder:11"/>
		<origin rpy="0 0 -0.20444" xyz="0.026783 -0.049912 0.748809"/>
		<axis xyz="0 0 -1"/>
	</joint>
	<link name="right_collarbone:11">
		<visual>
			<geometry>
				<mesh filename="package://iris_sandbox//2016_04_13_NICO/right_upper_arm_iam_e3e9c979.STL" scale="0.001 0.001 0.001"/>
			</geometry>
			<origin rpy="0 0 0" xyz="-0.0285 -0.054827 -0.000102"/>
			<material name="right_collarbone:11_color">
				<color rgba="0.176471 0.176471 0.176471 1"/>
			</material>
		</visual>
		<collision>
			<geometry>
				<mesh filename="package://iris_sandbox//2016_04_13_NICO/right_upper_arm_iam_e3e9c979.STL" scale="0.001 0.001 0.001"/>
			</geometry>
			<origin rpy="0 0 0" xyz="-0.0285 -0.054827 -0.000102"/>
		</collision>
		<inertial>
			<mass value="0.024811"/>
			<inertia ixx="0.000014" ixy="-0" ixz="0" iyy="0.000011" iyz="-0.000001" izz="0.000019"/>
			<origin rpy="0 0 0" xyz="-0 -0.041345 -0.002364"/>
		</inertial>
	</link>
	<joint name="right_collarbone:1--right_shoulder:11" type="continuous">
		<parent link="right_shoulder:11"/>
		<child link="right_collarbone:11"/>
		<origin rpy="0 0 0.20444" xyz="0.026211 -0.018056 0.037"/>
		<axis xyz="0 -1 0"/>
	</joint>
	<link name="right_upper_arm:11">
		<visual>
			<geometry>
				<mesh filename="package://iris_sandbox//2016_04_13_NICO/right_lower_arm1_iam_65a34910.STL" scale="0.001 0.001 0.001"/>
			</geometry>
			<origin rpy="0 0 0" xyz="-0.044001 -0.021 -0.139458"/>
			<material name="right_upper_arm:11_color">
				<color rgba="0.176471 0.176471 0.176471 1"/>
			</material>
		</visual>
		<collision>
			<geometry>
				<mesh filename="package://iris_sandbox//2016_04_13_NICO/right_lower_arm1_iam_65a34910.STL" scale="0.001 0.001 0.001"/>
			</geometry>
			<origin rpy="0 0 0" xyz="-0.044001 -0.021 -0.139458"/>
		</collision>
		<inertial>
			<mass value="0.189729"/>
			<inertia ixx="0.000851" ixy="0" ixz="0" iyy="0.000851" iyz="-0.000005" izz="0.000048"/>
			<origin rpy="0 0 0" xyz="-0.02306 -0.000321 -0.0866"/>
		</inertial>
	</link>
	<joint name="right_collarbone:1--right_upper_arm:11" type="continuous">
		<parent link="right_collarbone:11"/>
		<child link="right_upper_arm:11"/>
		<origin rpy="0 0 0" xyz="0.0245 -0.073664 -0.022853"/>
		<axis xyz="-1 0 0"/>
	</joint>
	<link name="right_lower_arm:11">
		<visual>
			<geometry>
				<mesh filename="package://iris_sandbox//2016_04_13_NICO/right_wrist_iam_771ea33e.STL" scale="0.001 0.001 0.001"/>
			</geometry>
			<origin rpy="0 0 0" xyz="-0.0168 -0.0018 -0.123873"/>
			<material name="right_lower_arm:11_color">
				<color rgba="0.176471 0.176471 0.176471 1"/>
			</material>
		</visual>
		<collision>
			<geometry>
				<mesh filename="package://iris_sandbox//2016_04_13_NICO/right_wrist_iam_771ea33e.STL" scale="0.001 0.001 0.001"/>
			</geometry>
			<origin rpy="0 0 0" xyz="-0.0168 -0.0018 -0.123873"/>
		</collision>
		<inertial>
			<mass value="0.076793"/>
			<inertia ixx="0.000104" ixy="-0" ixz="-0" iyy="0.000095" iyz="-0.000002" izz="0.000021"/>
			<origin rpy="0 0 0" xyz="0 0.022485 -0.081055"/>
		</inertial>
	</link>
	<joint name="right_lower_arm:1--right_upper_arm:11" type="continuous">
		<parent link="right_upper_arm:11"/>
		<child link="right_lower_arm:11"/>
		<origin rpy="0 0 0" xyz="-0.023001 -0.024001 -0.1732"/>
		<axis xyz="0 1 0"/>
	</joint>
	<link name="right_wrist:11">
		<visual>
			<geometry>
				<mesh filename="package://iris_sandbox//2016_04_13_NICO/forearm_ipt_64f921a1.STL" scale="0.001 0.001 0.001"/>
			</geometry>
			<origin rpy="0 0 0" xyz="0 0.011499 -0.002999"/>
			<material name="right_wrist:11_color">
				<color rgba="0.74902 0.74902 0.74902 1"/>
			</material>
		</visual>
		<collision>
			<geometry>
				<mesh filename="package://iris_sandbox//2016_04_13_NICO/forearm_ipt_64f921a1.STL" scale="0.001 0.001 0.001"/>
			</geometry>
			<origin rpy="0 0 0" xyz="0 0.011499 -0.002999"/>
		</collision>
		<inertial>
			<mass value="0.028397"/>
			<inertia ixx="0.000043" ixy="0.000004" ixz="-0" iyy="0.000029" iyz="-0.000007" izz="0.000058"/>
			<origin rpy="0 0 0" xyz="-0.000139 0.063 0.010993"/>
		</inertial>
	</link>
	<joint name="right_lower_arm:1--right_wrist:11" type="continuous">
		<parent link="right_lower_arm:11"/>
		<child link="right_wrist:11"/>
		<origin rpy="-1.570796 0 -3.071252" xyz="0 0.0102 -0.1286"/>
		<axis xyz="0 0 -1"/>
	</joint>
	<link name="right_palm:11">
		<visual>
			<geometry>
				<mesh filename="package://iris_sandbox//2016_04_13_NICO/hand_ipt_62fdccc0.STL" scale="0.001 0.001 0.001"/>
			</geometry>
			<origin rpy="0 0 0" xyz="-0.045308 -0.119397 -0.005504"/>
			<material name="right_palm:11_color">
				<color rgba="0.74902 0.74902 0.74902 1"/>
			</material>
		</visual>
		<collision>
			<geometry>
				<mesh filename="package://iris_sandbox//2016_04_13_NICO/hand_ipt_62fdccc0.STL" scale="0.001 0.001 0.001"/>
			</geometry>
			<origin rpy="0 0 0" xyz="-0.045308 -0.119397 -0.005504"/>
		</collision>
		<inertial>
			<mass value="0.005332"/>
			<inertia ixx="0.000006" ixy="-0.000004" ixz="0.000004" iyy="0.000015" iyz="0.000001" izz="0.000017"/>
			<origin rpy="0 0 0" xyz="-0.023967 -0.029511 0.002251"/>
		</inertial>
	</link>
	<joint name="right_palm:1--right_wrist:11" type="continuous">
		<parent link="right_wrist:11"/>
		<child link="right_palm:11"/>
		<origin rpy="-3.141592 0.245726 -1.570796" xyz="-0.023524 0.065837 -0.006115"/>
		<axis xyz="-0.997527 -0.0702828 0"/>
	</joint>
	<link name="right_finger2_segment1:11">
		<visual>
			<geometry>
				<mesh filename="package://iris_sandbox//2016_04_13_NICO/finger_segment_ipt_50d2a7f4.STL" scale="0.001 0.001 0.001"/>
			</geometry>
			<origin rpy="0 0 0" xyz="-0.006181 -0.015507 -0.007416"/>
			<material name="right_finger2_segment1:11_color">
				<color rgba="0.74902 0.74902 0.74902 1"/>
			</material>
		</visual>
		<collision>
			<geometry>
				<mesh filename="package://iris_sandbox//2016_04_13_NICO/finger_segment_ipt_50d2a7f4.STL" scale="0.001 0.001 0.001"/>
			</geometry>
			<origin rpy="0 0 0" xyz="-0.006181 -0.015507 -0.007416"/>
		</collision>
		<inertial>
			<mass value="0.000512"/>
			<inertia ixx="0" ixy="-0" ixz="-0" iyy="0" iyz="0" izz="0"/>
			<origin rpy="0 0 0" xyz="0.004999 0.000379 -0.008491"/>
		</inertial>
	</link>
	<joint name="right_palm:1--right_finger2_segment1:11" type="continuous">
		<parent link="right_palm:11"/>
		<child link="right_finger2_segment1:11"/>
		<origin rpy="-2.288732 -0 -1.507892" xyz="-0.0406 -0.03538 0.006226"/>
		<axis xyz="-0.996629 -0.0548897 0.0609743"/>
	</joint>
	<link name="right_finger2_segment2:21">
		<visual>
			<geometry>
				<mesh filename="package://iris_sandbox//2016_04_13_NICO/finger_segment_ipt_50d2a7f4.STL" scale="0.001 0.001 0.001"/>
			</geometry>
			<origin rpy="0 0 0" xyz="-0.016181 -0.015507 -0.007416"/>
			<material name="right_finger2_segment2:21_color">
				<color rgba="0.74902 0.74902 0.74902 1"/>
			</material>
		</visual>
		<collision>
			<geometry>
				<mesh filename="package://iris_sandbox//2016_04_13_NICO/finger_segment_ipt_50d2a7f4.STL" scale="0.001 0.001 0.001"/>
			</geometry>
			<origin rpy="0 0 0" xyz="-0.016181 -0.015507 -0.007416"/>
		</collision>
		<inertial>
			<mass value="0.000512"/>
			<inertia ixx="0" ixy="-0" ixz="-0" iyy="0" iyz="0" izz="0"/>
			<origin rpy="0 0 0" xyz="-0.005001 0.000379 -0.00849"/>
		</inertial>
	</link>
	<joint name="right_finger2_segment1:1--right_finger2_segment2:21" type="continuous">
		<parent link="right_finger2_segment1:11"/>
		<child link="right_finger2_segment2:21"/>
		<origin rpy="-0.286623 0 0" xyz="0.01 0.000001 -0.016001"/>
		<axis xyz="0.996629 0.0548897 -0.0609743"/>
	</joint>
	<link name="right_finger2_segment3:11">
		<visual>
			<geometry>
				<mesh filename="package://iris_sandbox//2016_04_13_NICO/fingertip_ipt_8417b8a9.STL" scale="0.001 0.001 0.001"/>
			</geometry>
			<origin rpy="0 0 0" xyz="-0.003986 0.000373 -0.01017"/>
			<material name="right_finger2_segment3:11_color">
				<color rgba="0.74902 0.74902 0.74902 1"/>
			</material>
		</visual>
		<collision>
			<geometry>
				<mesh filename="package://iris_sandbox//2016_04_13_NICO/fingertip_ipt_8417b8a9.STL" scale="0.001 0.001 0.001"/>
			</geometry>
			<origin rpy="0 0 0" xyz="-0.003986 0.000373 -0.01017"/>
		</collision>
		<inertial>
			<mass value="0.000598"/>
			<inertia ixx="0" ixy="0" ixz="-0" iyy="0" iyz="0" izz="0"/>
			<origin rpy="0 0 0" xyz="-0.0045 0.000081 -0.007077"/>
		</inertial>
	</link>
	<joint name="right_finger2_segment3:1--right_finger2_segment2:21" type="continuous">
		<parent link="right_finger2_segment2:21"/>
		<child link="right_finger2_segment3:11"/>
		<origin rpy="-0.567917 0 0" xyz="-0.0005 -0 -0.016"/>
		<axis xyz="-0.996629 -0.0548897 0.0609743"/>
	</joint>
	<link name="right_finger1_segment1:31">
		<visual>
			<geometry>
				<mesh filename="package://iris_sandbox//2016_04_13_NICO/finger_segment_ipt_50d2a7f4.STL" scale="0.001 0.001 0.001"/>
			</geometry>
			<origin rpy="0 0 0" xyz="-0.015681 -0.015506 -0.007416"/>
			<material name="right_finger1_segment1:31_color">
				<color rgba="0.74902 0.74902 0.74902 1"/>
			</material>
		</visual>
		<collision>
			<geometry>
				<mesh filename="package://iris_sandbox//2016_04_13_NICO/finger_segment_ipt_50d2a7f4.STL" scale="0.001 0.001 0.001"/>
			</geometry>
			<origin rpy="0 0 0" xyz="-0.015681 -0.015506 -0.007416"/>
		</collision>
		<inertial>
			<mass value="0.000512"/>
			<inertia ixx="0" ixy="-0" ixz="-0" iyy="0" iyz="0" izz="0"/>
			<origin rpy="0 0 0" xyz="-0.004501 0.00038 -0.00849"/>
		</inertial>
	</link>
	<joint name="right_finger1_segment1:3--right_palm:11" type="continuous">
		<parent link="right_palm:11"/>
		<child link="right_finger1_segment1:31"/>
		<origin rpy="-2.182402 -0 -1.6337" xyz="-0.040569 -0.010121 0.006226"/>
		<axis xyz="-0.994479 -0.085398 -0.0609743"/>
	</joint>
	<link name="right_finger1_segment2:41">
		<visual>
			<geometry>
				<mesh filename="package://iris_sandbox//2016_04_13_NICO/finger_segment_ipt_50d2a7f4.STL" scale="0.001 0.001 0.001"/>
			</geometry>
			<origin rpy="0 0 0" xyz="-0.015681 -0.015507 -0.007416"/>
			<material name="right_finger1_segment2:41_color">
				<color rgba="0.74902 0.74902 0.74902 1"/>
			</material>
		</visual>
		<collision>
			<geometry>
				<mesh filename="package://iris_sandbox//2016_04_13_NICO/finger_segment_ipt_50d2a7f4.STL" scale="0.001 0.001 0.001"/>
			</geometry>
			<origin rpy="0 0 0" xyz="-0.015681 -0.015507 -0.007416"/>
		</collision>
		<inertial>
			<mass value="0.000512"/>
			<inertia ixx="0" ixy="-0" ixz="-0" iyy="0" iyz="0" izz="0"/>
			<origin rpy="0 0 0" xyz="-0.004501 0.000379 -0.008491"/>
		</inertial>
	</link>
	<joint name="right_finger1_segment2:4--right_finger1_segment1:31" type="continuous">
		<parent link="right_finger1_segment1:31"/>
		<child link="right_finger1_segment2:41"/>
		<origin rpy="-0.499749 0 0" xyz="0 0 -0.016"/>
		<axis xyz="-0.994479 -0.085398 -0.0609743"/>
	</joint>
	<link name="right_finger1_segment3:21">
		<visual>
			<geometry>
				<mesh filename="package://iris_sandbox//2016_04_13_NICO/fingertip_ipt_8417b8a9.STL" scale="0.001 0.001 0.001"/>
			</geometry>
			<origin rpy="0 0 0" xyz="-0.003986 0.000373 -0.01017"/>
			<material name="right_finger1_segment3:21_color">
				<color rgba="0.74902 0.74902 0.74902 1"/>
			</material>
		</visual>
		<collision>
			<geometry>
				<mesh filename="package://iris_sandbox//2016_04_13_NICO/fingertip_ipt_8417b8a9.STL" scale="0.001 0.001 0.001"/>
			</geometry>
			<origin rpy="0 0 0" xyz="-0.003986 0.000373 -0.01017"/>
		</collision>
		<inertial>
			<mass value="0.000598"/>
			<inertia ixx="0" ixy="0" ixz="-0" iyy="0" iyz="0" izz="0"/>
			<origin rpy="0 0 0" xyz="-0.0045 0.00008 -0.007076"/>
		</inertial>
	</link>
	<joint name="right_finger1_segment3:2--right_finger1_segment2:41" type="continuous">
		<parent link="right_finger1_segment2:41"/>
		<child link="right_finger1_segment3:21"/>
		<origin rpy="-0.297921 0 0" xyz="0 -0 -0.016"/>
		<axis xyz="-0.994479 -0.085398 -0.0609743"/>
	</joint>
	<link name="right_thumb_segment1:51">
		<visual>
			<geometry>
				<mesh filename="package://iris_sandbox//2016_04_13_NICO/finger_segment_ipt_50d2a7f4.STL" scale="0.001 0.001 0.001"/>
			</geometry>
			<origin rpy="0 0 0" xyz="-0.006681 -0.015507 -0.007416"/>
			<material name="right_thumb_segment1:51_color">
				<color rgba="0.74902 0.74902 0.74902 1"/>
			</material>
		</visual>
		<collision>
			<geometry>
				<mesh filename="package://iris_sandbox//2016_04_13_NICO/finger_segment_ipt_50d2a7f4.STL" scale="0.001 0.001 0.001"/>
			</geometry>
			<origin rpy="0 0 0" xyz="-0.006681 -0.015507 -0.007416"/>
		</collision>
		<inertial>
			<mass value="0.000512"/>
			<inertia ixx="0" ixy="-0" ixz="-0" iyy="0" iyz="0" izz="0"/>
			<origin rpy="0 0 0" xyz="0.004499 0.00038 -0.00849"/>
		</inertial>
	</link>
	<joint name="right_thumb_segment1:5--right_palm:11" type="continuous">
		<parent link="right_palm:11"/>
		<child link="right_thumb_segment1:51"/>
		<origin rpy="2.875385 0 1.570796" xyz="-0.00842 -0.0275 0.0199"/>
		<axis xyz="-0.997527 -0.0702828 0"/>
	</joint>
	<link name="right_thumb_segment2:61">
		<visual>
			<geometry>
				<mesh filename="package://iris_sandbox//2016_04_13_NICO/finger_segment_ipt_50d2a7f4.STL" scale="0.001 0.001 0.001"/>
			</geometry>
			<origin rpy="0 0 0" xyz="-0.015681 -0.015506 -0.007416"/>
			<material name="right_thumb_segment2:61_color">
				<color rgba="0.74902 0.74902 0.74902 1"/>
			</material>
		</visual>
		<collision>
			<geometry>
				<mesh filename="package://iris_sandbox//2016_04_13_NICO/finger_segment_ipt_50d2a7f4.STL" scale="0.001 0.001 0.001"/>
			</geometry>
			<origin rpy="0 0 0" xyz="-0.015681 -0.015506 -0.007416"/>
		</collision>
		<inertial>
			<mass value="0.000512"/>
			<inertia ixx="0" ixy="-0" ixz="-0" iyy="0" iyz="0" izz="0"/>
			<origin rpy="0 0 0" xyz="-0.004501 0.00038 -0.00849"/>
		</inertial>
	</link>
	<joint name="right_thumb_segment2:6--right_thumb_segment1:51" type="continuous">
		<parent link="right_thumb_segment1:51"/>
		<child link="right_thumb_segment2:61"/>
		<origin rpy="-0.392674 0 0" xyz="0.009 -0.000001 -0.015999"/>
		<axis xyz="0.997527 0.0702828 0"/>
	</joint>
	<link name="right_thumb_segment3:31">
		<visual>
			<geometry>
				<mesh filename="package://iris_sandbox//2016_04_13_NICO/fingertip_ipt_8417b8a9.STL" scale="0.001 0.001 0.001"/>
			</geometry>
			<origin rpy="0 0 0" xyz="-0.003986 0.000373 -0.01017"/>
			<material name="right_thumb_segment3:31_color">
				<color rgba="0.74902 0.74902 0.74902 1"/>
			</material>
		</visual>
		<collision>
			<geometry>
				<mesh filename="package://iris_sandbox//2016_04_13_NICO/fingertip_ipt_8417b8a9.STL" scale="0.001 0.001 0.001"/>
			</geometry>
			<origin rpy="0 0 0" xyz="-0.003986 0.000373 -0.01017"/>
		</collision>
		<inertial>
			<mass value="0.000598"/>
			<inertia ixx="0" ixy="0" ixz="-0" iyy="0" iyz="0" izz="0"/>
			<origin rpy="0 0 0" xyz="-0.0045 0.000081 -0.007077"/>
		</inertial>
	</link>
	<joint name="right_thumb_segment3:3--right_thumb_segment2:61" type="continuous">
		<parent link="right_thumb_segment2:61"/>
		<child link="right_thumb_segment3:31"/>
		<origin rpy="-0.58665 0 0" xyz="0 0 -0.016"/>
		<axis xyz="0.997527 0.0702828 0"/>
	</joint>
</robot>

