

Joints left_hip_up_MIR:1--torso:11
Joints parent11
Joints left_hip_low_MIR:1--left_hip_up_MIR:11
Joints parent9
Joints left_thigh:1--left_hip_low_MIR:11
Joints parent31
Joints left_shank_MIR:1--left_thigh:11
Joints parent35
Joints left_ankle_MIR:1--left_shank_MIR:11
Joints parent5
Joints left_foot:1--left_ankle_MIR:11
Joints parent3

Joints right_hip_up:1--torso:11
Joints parent43
Joints right_hip_low:1--right_hip_up:11
Joints parent41
Joints right_thigh:1--right_hip_low:11
Joints parent13
Joints right_shank:1--right_thigh:11
Joints parent15
Joints right_ankle:1--right_shank:11
Joints parent49
Joints right_foot:1--right_ankle:11
Joints parent33




Joints right_shoulder:1--torso:11
Joints parent53
Joints right_upper_arm:1--right_shoulder:11
Joints parent19
Joints right_upper_arm:1--right_lower_arm:11
Joints parent17
Joints right_wrist:1--right_lower_arm:11
Joints parent21
Joints right_gripper:1--right_wrist:11
Joints parent27
Joints right_gripper_move:1--right_gripper:11
Joints parent29


Joints head:2--neck_old:11
Joints parent7
Joints neck_old:1--torso:11
Joints parent51


Joints left_shoulder:1--torso:11
Joints parent25
Joints left_upper_arm:1--left_shoulder:11
Joints parent23
Joints left_lower_arm:1--left_upper_arm:11
Joints parent37
Joints left_wrist_MIR:1--left_lower_arm:11
Joints parent39
Joints left_gripper_MIR:1--left_wrist_MIR:11
Joints parent45
Joints left_gripper_move:1--left_gripper_MIR:11
Joints parent47



<?xml version="1.0" ?>
<robot name="complete">
	<link name="torso:11">
		<visual>
			<geometry>
				<mesh filename="package://iris_sandbox//2015_10_21_NICU_with/torso_iam_fb80b350.stl" scale="0.001 0.001 0.001"/>
			</geometry>
			<origin rpy="0 0 0" xyz="-0.026368 -0.075212 0.525308"/>
			<material name="torso:11_color">
				<color rgba="0.270588 0.270588 0.270588 1"/>
			</material>
		</visual>
		<collision>
			<geometry>
				<mesh filename="package://iris_sandbox//2015_10_21_NICU_with/torso_iam_fb80b350.stl" scale="0.001 0.001 0.001"/>
			</geometry>
			<origin rpy="0 0 0" xyz="-0.026368 -0.075212 0.525308"/>
		</collision>
		<inertial>
			<mass value="0.599206"/>
			<inertia ixx="0.006204" ixy="0.000004" ixz="0.000252" iyy="0.005178" iyz="0.000001" izz="0.002039"/>
			<origin rpy="0 0 0" xyz="0.016202 -0.000123 0.648906"/>
		</inertial>
	</link>
	<link name="left_shoulder:11">
		<visual>
			<geometry>
				<mesh filename="package://iris_sandbox//2015_10_21_NICU_with/left_shoulder_iam_1ca4d925.stl" scale="0.001 0.001 0.001"/>
			</geometry>
			<origin rpy="0 0 0" xyz="0.022045 0.022577 0.037082"/>
			<material name="left_shoulder:11_color">
				<color rgba="0.176471 0.176471 0.176471 1"/>
			</material>
		</visual>
		<collision>
			<geometry>
				<mesh filename="package://iris_sandbox//2015_10_21_NICU_with/left_shoulder_iam_1ca4d925.stl" scale="0.001 0.001 0.001"/>
			</geometry>
			<origin rpy="0 0 0" xyz="0.022045 0.022577 0.037082"/>
		</collision>
		<inertial>
			<mass value="0.084038"/>
			<inertia ixx="0.000026" ixy="-0.000001" ixz="-0.000002" iyy="0.000034" iyz="-0" izz="0.000033"/>
			<origin rpy="0 0 0" xyz="0.0057 0.000259 0.033153"/>
		</inertial>
	</link>
	<joint name="left_shoulder:1--torso:11" type="continuous">
		<parent link="torso:11"/>
		<child link="left_shoulder:11"/>
		<origin rpy="0 0 -0.007848" xyz="0.026868 0.04375 0.749809"/>
		<axis xyz="0 0 -1"/>
	</joint>
	<link name="left_upper_arm:11">
		<visual>
			<geometry>
				<mesh filename="package://iris_sandbox//2015_10_21_NICU_with/left_upper_arm_iam_49d50008.stl" scale="0.001 0.001 0.001"/>
			</geometry>
			<origin rpy="0 0 0" xyz="-0.000321 -0.000277 0.000298"/>
			<material name="left_upper_arm:11_color">
				<color rgba="0.176471 0.176471 0.176471 1"/>
			</material>
		</visual>
		<collision>
			<geometry>
				<mesh filename="package://iris_sandbox//2015_10_21_NICU_with/left_upper_arm_iam_49d50008.stl" scale="0.001 0.001 0.001"/>
			</geometry>
			<origin rpy="0 0 0" xyz="-0.000321 -0.000277 0.000298"/>
		</collision>
		<inertial>
			<mass value="0.024811"/>
			<inertia ixx="0.000014" ixy="0" ixz="0" iyy="0.000011" iyz="0.000001" izz="0.000019"/>
			<origin rpy="0 0 0" xyz="-0 0.041346 -0.002365"/>
		</inertial>
	</link>
	<joint name="left_upper_arm:1--left_shoulder:11" type="continuous">
		<parent link="left_shoulder:11"/>
		<child link="left_upper_arm:11"/>
		<origin rpy="0 0.022689 -0.006359" xyz="0.022149 0.023361 0.037"/>
		<axis xyz="-0.0142069 -0.999899 0"/>
	</joint>
	<link name="left_lower_arm:11">
		<visual>
			<geometry>
				<mesh filename="package://iris_sandbox//2015_10_21_NICU_with/left_lower_arm_iam_5be2a521.stl" scale="0.001 0.001 0.001"/>
			</geometry>
			<origin rpy="0 0 0" xyz="-0.046901 -0.0229 -0.17117"/>
			<material name="left_lower_arm:11_color">
				<color rgba="0.176471 0.176471 0.176471 1"/>
			</material>
		</visual>
		<collision>
			<geometry>
				<mesh filename="package://iris_sandbox//2015_10_21_NICU_with/left_lower_arm_iam_5be2a521.stl" scale="0.001 0.001 0.001"/>
			</geometry>
			<origin rpy="0 0 0" xyz="-0.046901 -0.0229 -0.17117"/>
		</collision>
		<inertial>
			<mass value="0.192147"/>
			<inertia ixx="0.00087" ixy="0" ixz="-0.000003" iyy="0.00087" iyz="0.000003" izz="0.000049"/>
			<origin rpy="0 0 0" xyz="-0.02382 0.000181 -0.086599"/>
		</inertial>
	</link>
	<joint name="left_lower_arm:1--left_upper_arm:11" type="continuous">
		<parent link="left_upper_arm:11"/>
		<child link="left_lower_arm:11"/>
		<origin rpy="-0.010112 0 0" xyz="0.0245 0.073664 -0.022853"/>
		<axis xyz="0.999642 -0.0142032 -0.0226869"/>
	</joint>
	<link name="left_wrist_MIR:11">
		<visual>
			<geometry>
				<mesh filename="package://iris_sandbox//2015_10_21_NICU_with/right_wrist_mir_iam_dcfe6de3.stl" scale="0.001 0.001 0.001"/>
			</geometry>
			<origin rpy="0 0 0" xyz="0.000017 -0.010775 -0.125461"/>
			<material name="left_wrist_MIR:11_color">
				<color rgba="0.176471 0.176471 0.176471 1"/>
			</material>
		</visual>
		<collision>
			<geometry>
				<mesh filename="package://iris_sandbox//2015_10_21_NICU_with/right_wrist_mir_iam_dcfe6de3.stl" scale="0.001 0.001 0.001"/>
			</geometry>
			<origin rpy="0 0 0" xyz="0.000017 -0.010775 -0.125461"/>
		</collision>
		<inertial>
			<mass value="0.076791"/>
			<inertia ixx="0.000104" ixy="-0" ixz="-0" iyy="0.000095" iyz="0.000002" izz="0.000021"/>
			<origin rpy="0 0 0" xyz="0 -0.022486 -0.081055"/>
		</inertial>
	</link>
	<joint name="left_wrist_MIR:1--left_lower_arm:11" type="continuous">
		<parent link="left_lower_arm:11"/>
		<child link="left_wrist_MIR:11"/>
		<origin rpy="0 -0.000091 0" xyz="-0.024001 0.024001 -0.173199"/>
		<axis xyz="0.0139768 0.999851 -0.0101095"/>
	</joint>
	<link name="left_gripper_MIR:11">
		<visual>
			<geometry>
				<mesh filename="package://iris_sandbox//2015_10_21_NICU_with/right_gripper_mir_iam_56fa54a4.stl" scale="0.001 0.001 0.001"/>
			</geometry>
			<origin rpy="0 0 0" xyz="-0.01775 -0.0427 -0.032125"/>
			<material name="left_gripper_MIR:11_color">
				<color rgba="0.74902 0.74902 0.74902 1"/>
			</material>
		</visual>
		<collision>
			<geometry>
				<mesh filename="package://iris_sandbox//2015_10_21_NICU_with/right_gripper_mir_iam_56fa54a4.stl" scale="0.001 0.001 0.001"/>
			</geometry>
			<origin rpy="0 0 0" xyz="-0.01775 -0.0427 -0.032125"/>
		</collision>
		<inertial>
			<mass value="0.05064"/>
			<inertia ixx="0.000021" ixy="-0" ixz="-0" iyy="0.000015" iyz="-0.000004" izz="0.000018"/>
			<origin rpy="0 0 0" xyz="0.000281 -0.013871 -0.023149"/>
		</inertial>
	</link>
	<joint name="left_gripper_MIR:1--left_wrist_MIR:11" type="continuous">
		<parent link="left_wrist_MIR:11"/>
		<child link="left_gripper_MIR:11"/>
		<origin rpy="0 0 -0.01989" xyz="0 -0.0102 -0.125751"/>
		<axis xyz="-0.0227364 -0.00979004 -0.999694"/>
	</joint>
	<link name="left_gripper_move:11">
		<visual>
			<geometry>
				<mesh filename="package://iris_sandbox//2015_10_21_NICU_with/right_gripper_move_iam_12d81698.stl" scale="0.001 0.001 0.001"/>
			</geometry>
			<origin rpy="0 0 0" xyz="-0.001047 -0.000986 0.000348"/>
			<material name="left_gripper_move:11_color">
				<color rgba="0.74902 0.74902 0.74902 1"/>
			</material>
		</visual>
		<collision>
			<geometry>
				<mesh filename="package://iris_sandbox//2015_10_21_NICU_with/right_gripper_move_iam_12d81698.stl" scale="0.001 0.001 0.001"/>
			</geometry>
			<origin rpy="0 0 0" xyz="-0.001047 -0.000986 0.000348"/>
		</collision>
		<inertial>
			<mass value="0.008515"/>
			<inertia ixx="0.000007" ixy="0" ixz="0" iyy="0.000009" iyz="0.000002" izz="0.000004"/>
			<origin rpy="0 0 0" xyz="0.0205 -0.006927 -0.03756"/>
		</inertial>
	</link>
	<joint name="left_gripper_move:1--left_gripper_MIR:11" type="continuous">
		<parent link="left_gripper_MIR:11"/>
		<child link="left_gripper_move:11"/>
		<origin rpy="0.007568 0 3.141593" xyz="0.02075 -0 -0.021"/>
		<axis xyz="0.999168 -0.0340851 -0.0223906"/>
	</joint>
	<link name="right_hip_up:11">
		<visual>
			<geometry>
				<mesh filename="package://iris_sandbox//2015_10_21_NICU_with/right_hip_up_iam_f46f7684.stl" scale="0.001 0.001 0.001"/>
			</geometry>
			<origin rpy="0 0 0" xyz="-0.05 -0.018 -0.002769"/>
			<material name="right_hip_up:11_color">
				<color rgba="0.176471 0.176471 0.176471 1"/>
			</material>
		</visual>
		<collision>
			<geometry>
				<mesh filename="package://iris_sandbox//2015_10_21_NICU_with/right_hip_up_iam_f46f7684.stl" scale="0.001 0.001 0.001"/>
			</geometry>
			<origin rpy="0 0 0" xyz="-0.05 -0.018 -0.002769"/>
		</collision>
		<inertial>
			<mass value="0.027955"/>
			<inertia ixx="0.000011" ixy="-0" ixz="0.000004" iyy="0.000044" iyz="0" izz="0.000041"/>
			<origin rpy="0 0 0" xyz="0.004817 0.000019 -0.012064"/>
		</inertial>
	</link>
	<joint name="right_hip_up:1--torso:11" type="continuous">
		<parent link="torso:11"/>
		<child link="right_hip_up:11"/>
		<origin rpy="0 0 0.000571" xyz="0.010783 -0.055212 0.519208"/>
		<axis xyz="0 0 1"/>
	</joint>
	<link name="right_hip_low:11">
		<visual>
			<geometry>
				<mesh filename="package://iris_sandbox//2015_10_21_NICU_with/right_hip_up2_iam_f4f7d16a.stl" scale="0.001 0.001 0.001"/>
			</geometry>
			<origin rpy="0 0 0" xyz="0.0031 -0.023 -0.0252"/>
			<material name="right_hip_low:11_color">
				<color rgba="0.176471 0.176471 0.176471 1"/>
			</material>
		</visual>
		<collision>
			<geometry>
				<mesh filename="package://iris_sandbox//2015_10_21_NICU_with/right_hip_up2_iam_f4f7d16a.stl" scale="0.001 0.001 0.001"/>
			</geometry>
			<origin rpy="0 0 0" xyz="0.0031 -0.023 -0.0252"/>
		</collision>
		<inertial>
			<mass value="0.178341"/>
			<inertia ixx="0.000077" ixy="-0.000001" ixz="0.000001" iyy="0.000157" iyz="-0.000001" izz="0.00013"/>
			<origin rpy="0 0 0" xyz="0.04747 0.000227 -0.015464"/>
		</inertial>
	</link>
	<joint name="right_hip_low:1--right_hip_up:11" type="continuous">
		<parent link="right_hip_up:11"/>
		<child link="right_hip_low:11"/>
		<origin rpy="-0.031055 0 0" xyz="-0.046 0 -0.0414"/>
		<axis xyz="1 0.000570921 0"/>
	</joint>
	<link name="right_thigh:11">
		<visual>
			<geometry>
				<mesh filename="package://iris_sandbox//2015_10_21_NICU_with/thigh_right_complete_iam_6502f197.stl" scale="0.001 0.001 0.001"/>
			</geometry>
			<origin rpy="0 0 0" xyz="-0.04583 -0.056 -0.070384"/>
			<material name="right_thigh:11_color">
				<color rgba="0.176471 0.176471 0.176471 1"/>
			</material>
		</visual>
		<collision>
			<geometry>
				<mesh filename="package://iris_sandbox//2015_10_21_NICU_with/thigh_right_complete_iam_6502f197.stl" scale="0.001 0.001 0.001"/>
			</geometry>
			<origin rpy="0 0 0" xyz="-0.04583 -0.056 -0.070384"/>
		</collision>
		<inertial>
			<mass value="0.177251"/>
			<inertia ixx="0.000918" ixy="0.000001" ixz="-0.000093" iyy="0.000883" iyz="0.000003" izz="0.000125"/>
			<origin rpy="0 0 0" xyz="-0.029925 -0.02577 -0.151366"/>
		</inertial>
	</link>
	<joint name="right_thigh:1--right_hip_low:11" type="continuous">
		<parent link="right_hip_low:11"/>
		<child link="right_thigh:11"/>
		<origin rpy="0 -0.234454 0" xyz="0.0692 0.0261 0"/>
		<axis xyz="0.000570646 -0.999518 0.0310505"/>
	</joint>
	<link name="right_shank:11">
		<visual>
			<geometry>
				<mesh filename="package://iris_sandbox//2015_10_21_NICU_with/right_shank_iam_7a73fe91.stl" scale="0.001 0.001 0.001"/>
			</geometry>
			<origin rpy="0 0 0" xyz="-0.0049 -0.056 -0.081799"/>
			<material name="right_shank:11_color">
				<color rgba="0.176471 0.176471 0.176471 1"/>
			</material>
		</visual>
		<collision>
			<geometry>
				<mesh filename="package://iris_sandbox//2015_10_21_NICU_with/right_shank_iam_7a73fe91.stl" scale="0.001 0.001 0.001"/>
			</geometry>
			<origin rpy="0 0 0" xyz="-0.0049 -0.056 -0.081799"/>
		</collision>
		<inertial>
			<mass value="0.084704"/>
			<inertia ixx="0.000448" ixy="0" ixz="0.000025" iyy="0.000404" iyz="0" izz="0.000078"/>
			<origin rpy="0 0 0" xyz="0.015999 -0.026 -0.104866"/>
		</inertial>
	</link>
	<joint name="right_shank:1--right_thigh:11" type="continuous">
		<parent link="right_thigh:11"/>
		<child link="right_shank:11"/>
		<origin rpy="0 0.278258 0" xyz="-0.048258 0.0001 -0.214642"/>
		<axis xyz="-0.000570646 0.999518 -0.0310505"/>
	</joint>
	<link name="right_ankle:11">
		<visual>
			<geometry>
				<mesh filename="package://iris_sandbox//2015_10_21_NICU_with/right_ankle_iam_f4f7d16a.stl" scale="0.001 0.001 0.001"/>
			</geometry>
			<origin rpy="0 0 0" xyz="-0.0661 0.0031 -0.011201"/>
			<material name="right_ankle:11_color">
				<color rgba="0.176471 0.176471 0.176471 1"/>
			</material>
		</visual>
		<collision>
			<geometry>
				<mesh filename="package://iris_sandbox//2015_10_21_NICU_with/right_ankle_iam_f4f7d16a.stl" scale="0.001 0.001 0.001"/>
			</geometry>
			<origin rpy="0 0 0" xyz="-0.0661 0.0031 -0.011201"/>
		</collision>
		<inertial>
			<mass value="0.178341"/>
			<inertia ixx="0.000077" ixy="0.000001" ixz="-0.000001" iyy="0.000157" iyz="-0.000001" izz="0.00013"/>
			<origin rpy="0 0 0" xyz="-0.02173 0.025873 0.015465"/>
		</inertial>
	</link>
	<joint name="right_ankle:1--right_shank:11" type="continuous">
		<parent link="right_shank:11"/>
		<child link="right_ankle:11"/>
		<origin rpy="0 -0.000568 0" xyz="0.03924 -0.052 -0.216472"/>
		<axis xyz="-0.000570646 0.999518 -0.0310505"/>
	</joint>
	<link name="right_foot:11">
		<visual>
			<geometry>
				<mesh filename="package://iris_sandbox//2015_10_21_NICU_with/right_foot_iam_3ff7356a.stl" scale="0.001 0.001 0.001"/>
			</geometry>
			<origin rpy="0 0 0" xyz="-0.004 -0.024 -0.009365"/>
			<material name="right_foot:11_color">
				<color rgba="0.176471 0.176471 0.176471 1"/>
			</material>
		</visual>
		<collision>
			<geometry>
				<mesh filename="package://iris_sandbox//2015_10_21_NICU_with/right_foot_iam_3ff7356a.stl" scale="0.001 0.001 0.001"/>
			</geometry>
			<origin rpy="0 0 0" xyz="-0.004 -0.024 -0.009365"/>
		</collision>
		<inertial>
			<mass value="0.072801"/>
			<inertia ixx="0.000097" ixy="0.000003" ixz="-0.000001" iyy="0.000283" iyz="-0.000003" izz="0.000362"/>
			<origin rpy="0 0 0" xyz="0.074125 -0.00893 -0.031819"/>
		</inertial>
	</link>
	<joint name="right_foot:1--right_ankle:11" type="continuous">
		<parent link="right_ankle:11"/>
		<child link="right_foot:11"/>
		<origin rpy="0.046606 0 0" xyz="-0.0709 0.0261 0"/>
		<axis xyz="-0.999066 0.000771696 0.0432018"/>
	</joint>
	<link name="left_hip_up_MIR:11">
		<visual>
			<geometry>
				<mesh filename="package://iris_sandbox//2015_10_21_NICU_with/right_hip_up_mir_iam_386ac7b2.stl" scale="0.001 0.001 0.001"/>
			</geometry>
			<origin rpy="0 0 0" xyz="-0.05 -0.018 -0.0007"/>
			<material name="left_hip_up_MIR:11_color">
				<color rgba="0.176471 0.176471 0.176471 1"/>
			</material>
		</visual>
		<collision>
			<geometry>
				<mesh filename="package://iris_sandbox//2015_10_21_NICU_with/right_hip_up_mir_iam_386ac7b2.stl" scale="0.001 0.001 0.001"/>
			</geometry>
			<origin rpy="0 0 0" xyz="-0.05 -0.018 -0.0007"/>
		</collision>
		<inertial>
			<mass value="0.027955"/>
			<inertia ixx="0.000011" ixy="0" ixz="0.000004" iyy="0.000044" iyz="-0" izz="0.000041"/>
			<origin rpy="0 0 0" xyz="0.004817 -0.000001 -0.012063"/>
		</inertial>
	</link>
	<joint name="left_hip_up_MIR:1--torso:11" type="continuous">
		<parent link="torso:11"/>
		<child link="left_hip_up_MIR:11"/>
		<origin rpy="0 0 0.008271" xyz="0.010783 0.054788 0.519208"/>
		<axis xyz="0 0 -1"/>
	</joint>
	<link name="left_hip_low_MIR:11">
		<visual>
			<geometry>
				<mesh filename="package://iris_sandbox//2015_10_21_NICU_with/right_hip_up2_mir_iam_b8a74a0a.stl" scale="0.001 0.001 0.001"/>
			</geometry>
			<origin rpy="0 0 0" xyz="0.0031 -0.023 -0.025201"/>
			<material name="left_hip_low_MIR:11_color">
				<color rgba="0.176471 0.176471 0.176471 1"/>
			</material>
		</visual>
		<collision>
			<geometry>
				<mesh filename="package://iris_sandbox//2015_10_21_NICU_with/right_hip_up2_mir_iam_b8a74a0a.stl" scale="0.001 0.001 0.001"/>
			</geometry>
			<origin rpy="0 0 0" xyz="0.0031 -0.023 -0.025201"/>
		</collision>
		<inertial>
			<mass value="0.17834"/>
			<inertia ixx="0.000077" ixy="-0.000001" ixz="0.000001" iyy="0.000157" iyz="-0.000001" izz="0.00013"/>
			<origin rpy="0 0 0" xyz="0.04747 0.00023 -0.015465"/>
		</inertial>
	</link>
	<joint name="left_hip_low_MIR:1--left_hip_up_MIR:11" type="continuous">
		<parent link="left_hip_up_MIR:11"/>
		<child link="left_hip_low_MIR:11"/>
		<origin rpy="0.000434 0 0" xyz="-0.046 0 -0.0414"/>
		<axis xyz="-0.999966 -0.00827124 0"/>
	</joint>
	<link name="left_thigh:11">
		<visual>
			<geometry>
				<mesh filename="package://iris_sandbox//2015_10_21_NICU_with/thigh_left_complete_iam_5a6ba909.stl" scale="0.001 0.001 0.001"/>
			</geometry>
			<origin rpy="0 0 0" xyz="-0.04583 -0.056 -0.100647"/>
			<material name="left_thigh:11_color">
				<color rgba="0.176471 0.176471 0.176471 1"/>
			</material>
		</visual>
		<collision>
			<geometry>
				<mesh filename="package://iris_sandbox//2015_10_21_NICU_with/thigh_left_complete_iam_5a6ba909.stl" scale="0.001 0.001 0.001"/>
			</geometry>
			<origin rpy="0 0 0" xyz="-0.04583 -0.056 -0.100647"/>
		</collision>
		<inertial>
			<mass value="0.177251"/>
			<inertia ixx="0.000918" ixy="0.000001" ixz="-0.000093" iyy="0.000883" iyz="0.000003" izz="0.000125"/>
			<origin rpy="0 0 0" xyz="-0.029925 -0.02577 -0.151365"/>
		</inertial>
	</link>
	<joint name="left_thigh:1--left_hip_low_MIR:11" type="continuous">
		<parent link="left_hip_low_MIR:11"/>
		<child link="left_thigh:11"/>
		<origin rpy="0 -0.329409 0" xyz="0.0692 0.0261 -0"/>
		<axis xyz="0.00827124 -0.999966 -0.000434192"/>
	</joint>
	<link name="left_shank_MIR:11">
		<visual>
			<geometry>
				<mesh filename="package://iris_sandbox//2015_10_21_NICU_with/right_shank_mir_iam_a2a9b5d0.stl" scale="0.001 0.001 0.001"/>
			</geometry>
			<origin rpy="0 0 0" xyz="-0.004901 -0.056 -0.03453"/>
			<material name="left_shank_MIR:11_color">
				<color rgba="0.176471 0.176471 0.176471 1"/>
			</material>
		</visual>
		<collision>
			<geometry>
				<mesh filename="package://iris_sandbox//2015_10_21_NICU_with/right_shank_mir_iam_a2a9b5d0.stl" scale="0.001 0.001 0.001"/>
			</geometry>
			<origin rpy="0 0 0" xyz="-0.004901 -0.056 -0.03453"/>
		</collision>
		<inertial>
			<mass value="0.084704"/>
			<inertia ixx="0.000448" ixy="0" ixz="0.000025" iyy="0.000404" iyz="0" izz="0.000078"/>
			<origin rpy="0 0 0" xyz="0.015999 -0.026 -0.104866"/>
		</inertial>
	</link>
	<joint name="left_shank_MIR:1--left_thigh:11" type="continuous">
		<parent link="left_thigh:11"/>
		<child link="left_shank_MIR:11"/>
		<origin rpy="0 0.495699 0" xyz="-0.048258 0.0018 -0.214642"/>
		<axis xyz="-0.00827124 0.999966 0.000434192"/>
	</joint>
	<link name="left_ankle_MIR:11">
		<visual>
			<geometry>
				<mesh filename="package://iris_sandbox//2015_10_21_NICU_with/right_ankle_mir_iam_c5a384f4.stl" scale="0.001 0.001 0.001"/>
			</geometry>
			<origin rpy="0 0 0" xyz="-0.0661 -0.0491 0.025201"/>
			<material name="left_ankle_MIR:11_color">
				<color rgba="0.176471 0.176471 0.176471 1"/>
			</material>
		</visual>
		<collision>
			<geometry>
				<mesh filename="package://iris_sandbox//2015_10_21_NICU_with/right_ankle_mir_iam_c5a384f4.stl" scale="0.001 0.001 0.001"/>
			</geometry>
			<origin rpy="0 0 0" xyz="-0.0661 -0.0491 0.025201"/>
		</collision>
		<inertial>
			<mass value="0.17834"/>
			<inertia ixx="0.000077" ixy="-0.000001" ixz="-0.000001" iyy="0.000157" iyz="0.000001" izz="0.00013"/>
			<origin rpy="0 0 0" xyz="-0.02173 -0.025873 0.015465"/>
		</inertial>
	</link>
	<joint name="left_ankle_MIR:1--left_shank_MIR:11" type="continuous">
		<parent link="left_shank_MIR:11"/>
		<child link="left_ankle_MIR:11"/>
		<origin rpy="0 -0.120898 0" xyz="0.03924 0 -0.216472"/>
		<axis xyz="-0.00827124 0.999966 0.000434192"/>
	</joint>
	<link name="left_foot:11">
		<visual>
			<geometry>
				<mesh filename="package://iris_sandbox//2015_10_21_NICU_with/left_foot_iam_620666ef.stl" scale="0.001 0.001 0.001"/>
			</geometry>
			<origin rpy="0 0 0" xyz="-0.004 -0.024 -0.033621"/>
			<material name="left_foot:11_color">
				<color rgba="0.176471 0.176471 0.176471 1"/>
			</material>
		</visual>
		<collision>
			<geometry>
				<mesh filename="package://iris_sandbox//2015_10_21_NICU_with/left_foot_iam_620666ef.stl" scale="0.001 0.001 0.001"/>
			</geometry>
			<origin rpy="0 0 0" xyz="-0.004 -0.024 -0.033621"/>
		</collision>
		<inertial>
			<mass value="0.072801"/>
			<inertia ixx="0.000097" ixy="-0.000003" ixz="-0.000001" iyy="0.000283" iyz="0.000003" izz="0.000362"/>
			<origin rpy="0 0 0" xyz="0.074087 0.008929 -0.031819"/>
		</inertial>
	</link>
	<joint name="left_foot:1--left_ankle_MIR:11" type="continuous">
		<parent link="left_ankle_MIR:11"/>
		<child link="left_foot:11"/>
		<origin rpy="0.011381 0 0" xyz="-0.0709 -0.0261 0"/>
		<axis xyz="-0.998936 -0.00828242 0.0453772"/>
	</joint>
	<link name="neck_old:11">
		<visual>
			<geometry>
				<mesh filename="package://iris_sandbox//2015_10_21_NICU_with/neck_iam_61141f4f.stl" scale="0.001 0.001 0.001"/>
			</geometry>
			<origin rpy="0 0 0" xyz="-0.000115 -0.016098 0.074079"/>
			<material name="neck_old:11_color">
				<color rgba="0.176471 0.176471 0.176471 1"/>
			</material>
		</visual>
		<collision>
			<geometry>
				<mesh filename="package://iris_sandbox//2015_10_21_NICU_with/neck_iam_61141f4f.stl" scale="0.001 0.001 0.001"/>
			</geometry>
			<origin rpy="0 0 0" xyz="-0.000115 -0.016098 0.074079"/>
		</collision>
		<inertial>
			<mass value="0.090439"/>
			<inertia ixx="0.00006" ixy="-0" ixz="-0" iyy="0.000056" iyz="-0.000001" izz="0.000019"/>
			<origin rpy="0 0 0" xyz="0 0.000266 0.050352"/>
		</inertial>
	</link>
	<joint name="neck_old:1--torso:11" type="continuous">
		<parent link="torso:11"/>
		<child link="neck_old:11"/>
		<origin rpy="0 0 -0.005749" xyz="0.001283 -0.000212 0.756309"/>
		<axis xyz="0 0 1"/>
	</joint>
	<link name="head:21">
		<visual>
			<geometry>
				<mesh filename="package://iris_sandbox//2015_10_21_NICU_with/head_iam_b9cf2ea.stl" scale="0.001 0.001 0.001"/>
			</geometry>
			<origin rpy="0 0 0" xyz="-0.003998 -0.016462 0.04478"/>
			<material name="head:21_color">
				<color rgba="0.74902 0.74902 0.74902 1"/>
			</material>
		</visual>
		<collision>
			<geometry>
				<mesh filename="package://iris_sandbox//2015_10_21_NICU_with/head_iam_b9cf2ea.stl" scale="0.001 0.001 0.001"/>
			</geometry>
			<origin rpy="0 0 0" xyz="-0.003998 -0.016462 0.04478"/>
		</collision>
		<inertial>
			<mass value="0.264259"/>
			<inertia ixx="0.001354" ixy="0.000008" ixz="0.000093" iyy="0.001506" iyz="-0.000007" izz="0.001378"/>
			<origin rpy="0 0 0" xyz="0.013542 -0.02361 0.096944"/>
		</inertial>
	</link>
	<joint name="head:2--neck_old:11" type="continuous">
		<parent link="neck_old:11"/>
		<child link="head:21"/>
		<origin rpy="0 0 0" xyz="0 0.023001 0.0745"/>
		<axis xyz="0.00574871 0.999983 0"/>
	</joint>
	<link name="right_shoulder:11">
		<visual>
			<geometry>
				<mesh filename="package://iris_sandbox//2015_10_21_NICU_with/right_shoulder_iam_34db21c8.stl" scale="0.001 0.001 0.001"/>
			</geometry>
			<origin rpy="0 0 0" xyz="-0.026868 0.044174 -0.750309"/>
			<material name="right_shoulder:11_color">
				<color rgba="0.176471 0.176471 0.176471 1"/>
			</material>
		</visual>
		<collision>
			<geometry>
				<mesh filename="package://iris_sandbox//2015_10_21_NICU_with/right_shoulder_iam_34db21c8.stl" scale="0.001 0.001 0.001"/>
			</geometry>
			<origin rpy="0 0 0" xyz="-0.026868 0.044174 -0.750309"/>
		</collision>
		<inertial>
			<mass value="0.084038"/>
			<inertia ixx="0.000026" ixy="0.000001" ixz="-0.000002" iyy="0.000034" iyz="0" izz="0.000033"/>
			<origin rpy="0 0 0" xyz="0.005688 -0.000444 0.033153"/>
		</inertial>
	</link>
	<joint name="right_shoulder:1--torso:11" type="continuous">
		<parent link="torso:11"/>
		<child link="right_shoulder:11"/>
		<origin rpy="0 0 0.017102" xyz="0.026868 -0.044174 0.750309"/>
		<axis xyz="0 0 -1"/>
	</joint>
	<link name="right_upper_arm:11">
		<visual>
			<geometry>
				<mesh filename="package://iris_sandbox//2015_10_21_NICU_with/right_upper_arm_iam_e3e9c979.stl" scale="0.001 0.001 0.001"/>
			</geometry>
			<origin rpy="0 0 0" xyz="0.000219 -0.000159 -0.000121"/>
			<material name="right_upper_arm:11_color">
				<color rgba="0.176471 0.176471 0.176471 1"/>
			</material>
		</visual>
		<collision>
			<geometry>
				<mesh filename="package://iris_sandbox//2015_10_21_NICU_with/right_upper_arm_iam_e3e9c979.stl" scale="0.001 0.001 0.001"/>
			</geometry>
			<origin rpy="0 0 0" xyz="0.000219 -0.000159 -0.000121"/>
		</collision>
		<inertial>
			<mass value="0.024811"/>
			<inertia ixx="0.000014" ixy="-0" ixz="-0" iyy="0.000011" iyz="0.000001" izz="0.000019"/>
			<origin rpy="0 0 0" xyz="0 0.041345 -0.002364"/>
		</inertial>
	</link>
	<joint name="right_upper_arm:1--right_shoulder:11" type="continuous">
		<parent link="right_shoulder:11"/>
		<child link="right_upper_arm:11"/>
		<origin rpy="0 -0.01432 3.115413" xyz="0.021377 -0.024069 0.037"/>
		<axis xyz="-0.00907744 -0.999959 0"/>
	</joint>
	<link name="right_lower_arm:11">
		<visual>
			<geometry>
				<mesh filename="package://iris_sandbox//2015_10_21_NICU_with/right_lower_arm1_iam_65a34910.stl" scale="0.001 0.001 0.001"/>
			</geometry>
			<origin rpy="0 0 0" xyz="-0.023159 -0.001162 -0.173272"/>
			<material name="right_lower_arm:11_color">
				<color rgba="0.176471 0.176471 0.176471 1"/>
			</material>
		</visual>
		<collision>
			<geometry>
				<mesh filename="package://iris_sandbox//2015_10_21_NICU_with/right_lower_arm1_iam_65a34910.stl" scale="0.001 0.001 0.001"/>
			</geometry>
			<origin rpy="0 0 0" xyz="-0.023159 -0.001162 -0.173272"/>
		</collision>
		<inertial>
			<mass value="0.192147"/>
			<inertia ixx="0.00087" ixy="0" ixz="0.000002" iyy="0.00087" iyz="-0.000003" izz="0.000049"/>
			<origin rpy="0 0 0" xyz="-0.023201 -0.000181 -0.0866"/>
		</inertial>
	</link>
	<joint name="right_upper_arm:1--right_lower_arm:11" type="continuous">
		<parent link="right_upper_arm:11"/>
		<child link="right_lower_arm:11"/>
		<origin rpy="-0.033965 0 3.141593" xyz="-0.0245 0.073664 -0.022853"/>
		<axis xyz="-0.999856 0.00907651 0.0143192"/>
	</joint>
	<link name="right_wrist:11">
		<visual>
			<geometry>
				<mesh filename="package://iris_sandbox//2015_10_21_NICU_with/right_wrist_iam_771ea33e.stl" scale="0.001 0.001 0.001"/>
			</geometry>
			<origin rpy="0 0 0" xyz="-0.0168 -0.001799 -0.123873"/>
			<material name="right_wrist:11_color">
				<color rgba="0.176471 0.176471 0.176471 1"/>
			</material>
		</visual>
		<collision>
			<geometry>
				<mesh filename="package://iris_sandbox//2015_10_21_NICU_with/right_wrist_iam_771ea33e.stl" scale="0.001 0.001 0.001"/>
			</geometry>
			<origin rpy="0 0 0" xyz="-0.0168 -0.001799 -0.123873"/>
		</collision>
		<inertial>
			<mass value="0.076793"/>
			<inertia ixx="0.000104" ixy="-0" ixz="-0" iyy="0.000095" iyz="-0.000002" izz="0.000021"/>
			<origin rpy="0 0 0" xyz="0 0.022486 -0.081055"/>
		</inertial>
	</link>
	<joint name="right_wrist:1--right_lower_arm:11" type="continuous">
		<parent link="right_lower_arm:11"/>
		<child link="right_wrist:11"/>
		<origin rpy="0 0.019724 0" xyz="-0.023001 -0.024002 -0.1732"/>
		<axis xyz="0.00858597 0.999386 -0.0339549"/>
	</joint>
	<link name="right_gripper:11">
		<visual>
			<geometry>
				<mesh filename="package://iris_sandbox//2015_10_21_NICU_with/right_gripper_iam_b0678a8.stl" scale="0.001 0.001 0.001"/>
			</geometry>
			<origin rpy="0 0 0" xyz="0.022303 -0.000203 -0.021074"/>
			<material name="right_gripper:11_color">
				<color rgba="0.74902 0.74902 0.74902 1"/>
			</material>
		</visual>
		<collision>
			<geometry>
				<mesh filename="package://iris_sandbox//2015_10_21_NICU_with/right_gripper_iam_b0678a8.stl" scale="0.001 0.001 0.001"/>
			</geometry>
			<origin rpy="0 0 0" xyz="0.022303 -0.000203 -0.021074"/>
		</collision>
		<inertial>
			<mass value="0.05064"/>
			<inertia ixx="0.000021" ixy="0" ixz="-0" iyy="0.000015" iyz="0.000004" izz="0.000018"/>
			<origin rpy="0 0 0" xyz="0.000282 0.013871 -0.02315"/>
		</inertial>
	</link>
	<joint name="right_gripper:1--right_wrist:11" type="continuous">
		<parent link="right_wrist:11"/>
		<child link="right_gripper:11"/>
		<origin rpy="0 0 -0.043493" xyz="0 0.010201 -0.12575"/>
		<axis xyz="0.0343356 0.0336415 0.998844"/>
	</joint>
	<link name="right_gripper_move:11">
		<visual>
			<geometry>
				<mesh filename="package://iris_sandbox//2015_10_21_NICU_with/right_gripper_move_iam_12d81698.stl" scale="0.001 0.001 0.001"/>
			</geometry>
			<origin rpy="0 0 0" xyz="-0.042047 -0.000987 0.000348"/>
			<material name="right_gripper_move:11_color">
				<color rgba="0.74902 0.74902 0.74902 1"/>
			</material>
		</visual>
		<collision>
			<geometry>
				<mesh filename="package://iris_sandbox//2015_10_21_NICU_with/right_gripper_move_iam_12d81698.stl" scale="0.001 0.001 0.001"/>
			</geometry>
			<origin rpy="0 0 0" xyz="-0.042047 -0.000987 0.000348"/>
		</collision>
		<inertial>
			<mass value="0.008515"/>
			<inertia ixx="0.000007" ixy="0" ixz="0" iyy="0.000009" iyz="0.000002" izz="0.000004"/>
			<origin rpy="0 0 0" xyz="-0.0205 -0.006927 -0.03756"/>
		</inertial>
	</link>
	<joint name="right_gripper_move:1--right_gripper:11" type="continuous">
		<parent link="right_gripper:11"/>
		<child link="right_gripper_move:11"/>
		<origin rpy="-0.012102 0 0" xyz="0.02075 0 -0.021001"/>
		<axis xyz="-0.998055 0.0531849 0.0325172"/>
	</joint>
</robot>

