<?xml version="1.0" ?>
<robot name="complete">
	<link name="ass_torso:11">
		<visual>
			<geometry>
				<mesh filename="package://iris_sandbox//2015_08_12_NICU/ass_torso_iam_fb80b350.stl" scale="0.001 0.001 0.001"/>
			</geometry>
			<origin rpy="0 0 0" xyz="-0.026368 -0.075212 0.525308"/>
			<material name="ass_torso:11_color">
				<color rgba="0.74902 0.74902 0.74902 1"/>
			</material>
		</visual>
		<collision>
			<geometry>
				<mesh filename="package://iris_sandbox//2015_08_12_NICU/ass_torso_iam_fb80b350.stl" scale="0.001 0.001 0.001"/>
			</geometry>
			<origin rpy="0 0 0" xyz="-0.026368 -0.075212 0.525308"/>
		</collision>
		<inertial>
			<mass value="0.599206"/>
			<inertia ixx="0.006204" ixy="0.000004" ixz="0.000252" iyy="0.005178" iyz="0.000001" izz="0.002039"/>
			<origin rpy="0 0 0" xyz="0.016202 -0.000123 0.648906"/>
		</inertial>
	</link>
	<link name="ass_neck:11">
		<visual>
			<geometry>
				<mesh filename="package://iris_sandbox//2015_08_12_NICU/ass_neck_iam_61141f4f.stl" scale="0.001 0.001 0.001"/>
			</geometry>
			<origin rpy="0 0 0" xyz="-0.000115 -0.016098 0.054079"/>
			<material name="ass_neck:11_color">
				<color rgba="0.74902 0.74902 0.74902 1"/>
			</material>
		</visual>
		<collision>
			<geometry>
				<mesh filename="package://iris_sandbox//2015_08_12_NICU/ass_neck_iam_61141f4f.stl" scale="0.001 0.001 0.001"/>
			</geometry>
			<origin rpy="0 0 0" xyz="-0.000115 -0.016098 0.054079"/>
		</collision>
		<inertial>
			<mass value="0.07908"/>
			<inertia ixx="0.000037" ixy="-0" ixz="0" iyy="0.000033" iyz="-0.000001" izz="0.000018"/>
			<origin rpy="0 0 0" xyz="0 0.000304 0.036259"/>
		</inertial>
	</link>
	<joint name="neck_low" type="revolute">
		<parent link="ass_torso:11"/>
		<child link="ass_neck:11"/>
		<origin rpy="0 0 -0.00548" xyz="0.001283 -0.000212 0.756309"/>
		<axis xyz="0 0 1"/>
		<limit effort="30" lower="-2.094" upper="0.698132" velocity="1"/>
	</joint>
	<link name="ass_head:11">
		<visual>
			<geometry>
				<mesh filename="package://iris_sandbox//2015_08_12_NICU/ass_head_iam_b9cf2ea.stl" scale="0.001 0.001 0.001"/>
			</geometry>
			<origin rpy="0 0 0" xyz="-0.003998 -0.016462 0.04478"/>
			<material name="ass_head:11_color">
				<color rgba="0.74902 0.74902 0.74902 1"/>
			</material>
		</visual>
		<collision>
			<geometry>
				<mesh filename="package://iris_sandbox//2015_08_12_NICU/ass_head_iam_b9cf2ea.stl" scale="0.001 0.001 0.001"/>
			</geometry>
			<origin rpy="0 0 0" xyz="-0.003998 -0.016462 0.04478"/>
		</collision>
		<inertial>
			<mass value="0.179424"/>
			<inertia ixx="0.000925" ixy="0.000002" ixz="0.000013" iyy="0.000799" iyz="-0.000005" izz="0.000625"/>
			<origin rpy="0 0 0" xyz="0.041963 -0.023987 0.090634"/>
		</inertial>
	</link>
	<joint name="neck_up" type="revolute">
		<parent link="ass_neck:11"/>
		<child link="ass_head:11"/>
		<origin rpy="0 0.001631 0" xyz="0 0.023001 0.0545"/>
		<axis xyz="0 1 0"/>
		<limit effort="30" lower="-0.785398" upper="0.33161" velocity="1"/>
	</joint>
	<link name="ass_right_shoulder:11">
		<visual>
			<geometry>
				<mesh filename="package://iris_sandbox//2015_08_12_NICU/ass_right_shoulder_iam_34db21c8.stl" scale="0.001 0.001 0.001"/>
			</geometry>
			<origin rpy="0 0 0" xyz="-0.026868 0.044174 -0.750309"/>
			<material name="ass_right_shoulder:11_color">
				<color rgba="0.74902 0.74902 0.74902 1"/>
			</material>
		</visual>
		<collision>
			<geometry>
				<mesh filename="package://iris_sandbox//2015_08_12_NICU/ass_right_shoulder_iam_34db21c8.stl" scale="0.001 0.001 0.001"/>
			</geometry>
			<origin rpy="0 0 0" xyz="-0.026868 0.044174 -0.750309"/>
		</collision>
		<inertial>
			<mass value="0.084038"/>
			<inertia ixx="0.000026" ixy="0.000001" ixz="-0.000002" iyy="0.000034" iyz="0" izz="0.000033"/>
			<origin rpy="0 0 0" xyz="0.005688 -0.000444 0.033153"/>
		</inertial>
	</link>
	<joint name="right_shoulder" type="revolute">
		<parent link="ass_torso:11"/>
		<child link="ass_right_shoulder:11"/>
		<origin rpy="0 0 0.045167" xyz="0.026868 -0.044174 0.750309"/>
		<axis xyz="0 0 1"/>
		<limit effort="30" lower="-0.087266" upper="1.57" velocity="1"/>
	</joint>
	<link name="ass_right_upper_arm:11">
		<visual>
			<geometry>
				<mesh filename="package://iris_sandbox//2015_08_12_NICU/ass_right_upper_arm_iam_b2120f31.stl" scale="0.001 0.001 0.001"/>
			</geometry>
			<origin rpy="0 0 0" xyz="0.000201 -0.054474 0.000369"/>
			<material name="ass_right_upper_arm:11_color">
				<color rgba="0.74902 0.74902 0.74902 1"/>
			</material>
		</visual>
		<collision>
			<geometry>
				<mesh filename="package://iris_sandbox//2015_08_12_NICU/ass_right_upper_arm_iam_b2120f31.stl" scale="0.001 0.001 0.001"/>
			</geometry>
			<origin rpy="0 0 0" xyz="0.000201 -0.054474 0.000369"/>
		</collision>
		<inertial>
			<mass value="0.024811"/>
			<inertia ixx="0.000014" ixy="-0" ixz="0" iyy="0.000011" iyz="-0.000001" izz="0.000019"/>
			<origin rpy="0 0 0" xyz="0 -0.041346 -0.002364"/>
		</inertial>
	</link>
	<joint name="right_shoulder_upper_arm" type="revolute">
		<parent link="ass_right_shoulder:11"/>
		<child link="ass_right_upper_arm:11"/>
		<origin rpy="0 -0.054343 -0.02618" xyz="0.021377 -0.024069 0.037"/>
		<axis xyz="0 1 0"/>
		<limit effort="30" lower="-0.663225" upper="2.44346" velocity="1"/>
	</joint>
	<link name="ass_right_lower_arm:11">
		<visual>
			<geometry>
				<mesh filename="package://iris_sandbox//2015_08_12_NICU/ass_right_lower_arm1_iam_65a34910.stl" scale="0.001 0.001 0.001"/>
			</geometry>
			<origin rpy="0 0 0" xyz="-0.023159 -0.001161 -0.173272"/>
			<material name="ass_right_lower_arm:11_color">
				<color rgba="0.74902 0.74902 0.74902 1"/>
			</material>
		</visual>
		<collision>
			<geometry>
				<mesh filename="package://iris_sandbox//2015_08_12_NICU/ass_right_lower_arm1_iam_65a34910.stl" scale="0.001 0.001 0.001"/>
			</geometry>
			<origin rpy="0 0 0" xyz="-0.023159 -0.001161 -0.173272"/>
		</collision>
		<inertial>
			<mass value="0.192147"/>
			<inertia ixx="0.00087" ixy="0" ixz="0.000002" iyy="0.00087" iyz="-0.000003" izz="0.000049"/>
			<origin rpy="0 0 0" xyz="-0.023201 -0.000181 -0.086601"/>
		</inertial>
	</link>
	<joint name="right_upper_arm" type="revolute">
		<parent link="ass_right_upper_arm:11"/>
		<child link="ass_right_lower_arm:11"/>
		<origin rpy="-0.034907 0 0" xyz="0.0245 -0.073664 -0.022852"/>
		<axis xyz="1 0 0"/>
		<limit effort="30" lower="-0.942478" upper="1.22173" velocity="1"/>
	</joint>
	<link name="ass_right_wrist:11">
		<visual>
			<geometry>
				<mesh filename="package://iris_sandbox//2015_08_12_NICU/ass_right_wrist_iam_771ea33e.stl" scale="0.001 0.001 0.001"/>
			</geometry>
			<origin rpy="0 0 0" xyz="-0.0168 -0.0018 -0.123873"/>
			<material name="ass_right_wrist:11_color">
				<color rgba="0.74902 0.74902 0.74902 1"/>
			</material>
		</visual>
		<collision>
			<geometry>
				<mesh filename="package://iris_sandbox//2015_08_12_NICU/ass_right_wrist_iam_771ea33e.stl" scale="0.001 0.001 0.001"/>
			</geometry>
			<origin rpy="0 0 0" xyz="-0.0168 -0.0018 -0.123873"/>
		</collision>
		<inertial>
			<mass value="0.076793"/>
			<inertia ixx="0.000104" ixy="-0" ixz="-0" iyy="0.000095" iyz="-0.000002" izz="0.000021"/>
			<origin rpy="0 0 0" xyz="0 0.022485 -0.081055"/>
		</inertial>
	</link>
	<joint name="right_lower_arm" type="revolute">
		<parent link="ass_right_lower_arm:11"/>
		<child link="ass_right_wrist:11"/>
		<origin rpy="0 0.019724 0" xyz="-0.023001 -0.024001 -0.1732"/>
		<axis xyz="0 1 0"/>
		<limit effort="30" lower="-1.48353" upper="0.17453" velocity="1"/>
	</joint>
	<link name="ass_right_gripper:11">
		<visual>
			<geometry>
				<mesh filename="package://iris_sandbox//2015_08_12_NICU/ass_right_gripper_iam_b0678a8.stl" scale="0.001 0.001 0.001"/>
			</geometry>
			<origin rpy="0 0 0" xyz="0.022303 -0.000202 -0.021073"/>
			<material name="ass_right_gripper:11_color">
				<color rgba="0.74902 0.74902 0.74902 1"/>
			</material>
		</visual>
		<collision>
			<geometry>
				<mesh filename="package://iris_sandbox//2015_08_12_NICU/ass_right_gripper_iam_b0678a8.stl" scale="0.001 0.001 0.001"/>
			</geometry>
			<origin rpy="0 0 0" xyz="0.022303 -0.000202 -0.021073"/>
		</collision>
		<inertial>
			<mass value="0.05064"/>
			<inertia ixx="0.000021" ixy="0" ixz="-0" iyy="0.000015" iyz="0.000004" izz="0.000018"/>
			<origin rpy="0 0 0" xyz="0.000282 0.013872 -0.023149"/>
		</inertial>
	</link>
	<joint name="right_wrist" type="revolute">
		<parent link="ass_right_wrist:11"/>
		<child link="ass_right_gripper:11"/>
		<origin rpy="0 0 -0.043493" xyz="0 0.0102 -0.12575"/>
		<axis xyz="0 0 1"/>
		<limit effort="30" lower="-3.124139" upper="3.124139" velocity="1"/>
	</joint>
	<link name="ass_right_gripper_move:11">
		<visual>
			<geometry>
				<mesh filename="package://iris_sandbox//2015_08_12_NICU/ass_right_gripper_move_iam_12d81698.stl" scale="0.001 0.001 0.001"/>
			</geometry>
			<origin rpy="0 0 0" xyz="-0.042047 -0.000986 0.000348"/>
			<material name="ass_right_gripper_move:11_color">
				<color rgba="0.74902 0.74902 0.74902 1"/>
			</material>
		</visual>
		<collision>
			<geometry>
				<mesh filename="package://iris_sandbox//2015_08_12_NICU/ass_right_gripper_move_iam_12d81698.stl" scale="0.001 0.001 0.001"/>
			</geometry>
			<origin rpy="0 0 0" xyz="-0.042047 -0.000986 0.000348"/>
		</collision>
		<inertial>
			<mass value="0.008515"/>
			<inertia ixx="0.000007" ixy="0" ixz="0" iyy="0.000009" iyz="0.000002" izz="0.000004"/>
			<origin rpy="0 0 0" xyz="-0.0205 -0.006927 -0.037561"/>
		</inertial>
	</link>
	<joint name="right_gripper" type="revolute">
		<parent link="ass_right_gripper:11"/>
		<child link="ass_right_gripper_move:11"/>
		<origin rpy="-0.012102 0 0" xyz="0.02075 0 -0.021"/>
		<axis xyz="-0.999031 0.0251771 -0.0361064"/>
		<limit effort="30" lower="-0.610865" upper="0.837758" velocity="1"/>
	</joint>
	<link name="ass_right_hip_up:11">
		<visual>
			<geometry>
				<mesh filename="package://iris_sandbox//2015_08_12_NICU/ass_right_hip_up_iam_f46f7684.stl" scale="0.001 0.001 0.001"/>
			</geometry>
			<origin rpy="0 0 0" xyz="-0.05 -0.018 -0.002769"/>
			<material name="ass_right_hip_up:11_color">
				<color rgba="0.74902 0.74902 0.74902 1"/>
			</material>
		</visual>
		<collision>
			<geometry>
				<mesh filename="package://iris_sandbox//2015_08_12_NICU/ass_right_hip_up_iam_f46f7684.stl" scale="0.001 0.001 0.001"/>
			</geometry>
			<origin rpy="0 0 0" xyz="-0.05 -0.018 -0.002769"/>
		</collision>
		<inertial>
			<mass value="0.073394"/>
			<inertia ixx="0.000029" ixy="-0" ixz="0.00001" iyy="0.000118" iyz="0" izz="0.000109"/>
			<origin rpy="0 0 0" xyz="0.004972 0.000019 -0.01248"/>
		</inertial>
	</link>
	<joint name="right_hip_up_z" type="revolute">
		<parent link="ass_torso:11"/>
		<child link="ass_right_hip_up:11"/>
		<origin rpy="0 0 0.000571" xyz="0.010783 -0.055212 0.519208"/>
		<axis xyz="0 0 1"/>
		<limit effort="30" lower="-0.698132" upper="0.698132" velocity="1"/>
	</joint>
	<link name="ass_right_hip_low:11">
		<visual>
			<geometry>
				<mesh filename="package://iris_sandbox//2015_08_12_NICU/ass_right_hip_up2_iam_f4f7d16a.stl" scale="0.001 0.001 0.001"/>
			</geometry>
			<origin rpy="0 0 0" xyz="0.0031 -0.023 -0.0252"/>
			<material name="ass_right_hip_low:11_color">
				<color rgba="0.74902 0.74902 0.74902 1"/>
			</material>
		</visual>
		<collision>
			<geometry>
				<mesh filename="package://iris_sandbox//2015_08_12_NICU/ass_right_hip_up2_iam_f4f7d16a.stl" scale="0.001 0.001 0.001"/>
			</geometry>
			<origin rpy="0 0 0" xyz="0.0031 -0.023 -0.0252"/>
		</collision>
		<inertial>
			<mass value="0.178341"/>
			<inertia ixx="0.000077" ixy="-0.000001" ixz="0.000001" iyy="0.000157" iyz="-0.000001" izz="0.00013"/>
			<origin rpy="0 0 0" xyz="0.04747 0.000227 -0.015464"/>
		</inertial>
	</link>
	<joint name="right_hip_up_x" type="revolute">
		<parent link="ass_right_hip_up:11"/>
		<child link="ass_right_hip_low:11"/>
		<origin rpy="-0.031055 0 0" xyz="-0.046 0 -0.0414"/>
		<axis xyz="1 0 0"/>
		<limit effort="30" lower="-1.22173" upper="0.418879" velocity="1"/>
	</joint>
	<link name="ass_right_thigh:11">
		<visual>
			<geometry>
				<mesh filename="package://iris_sandbox//2015_08_12_NICU/ass_thigh_right_complete_iam_6502f197.stl" scale="0.001 0.001 0.001"/>
			</geometry>
			<origin rpy="0 0 0" xyz="-0.04583 -0.056 -0.070384"/>
			<material name="ass_right_thigh:11_color">
				<color rgba="0.74902 0.74902 0.74902 1"/>
			</material>
		</visual>
		<collision>
			<geometry>
				<mesh filename="package://iris_sandbox//2015_08_12_NICU/ass_thigh_right_complete_iam_6502f197.stl" scale="0.001 0.001 0.001"/>
			</geometry>
			<origin rpy="0 0 0" xyz="-0.04583 -0.056 -0.070384"/>
		</collision>
		<inertial>
			<mass value="0.177251"/>
			<inertia ixx="0.000918" ixy="0.000001" ixz="-0.000093" iyy="0.000883" iyz="0.000003" izz="0.000125"/>
			<origin rpy="0 0 0" xyz="-0.029925 -0.02577 -0.151366"/>
		</inertial>
	</link>
	<joint name="right_hip_up_y" type="revolute">
		<parent link="ass_right_hip_low:11"/>
		<child link="ass_right_thigh:11"/>
		<origin rpy="0 -0.234454 0" xyz="0.0692 0.0261 0"/>
		<axis xyz="0 1 0"/>
		<limit effort="30" lower="-0.5585" upper="1.570796" velocity="1"/>
	</joint>
	<link name="ass_right_shank:11">
		<visual>
			<geometry>
				<mesh filename="package://iris_sandbox//2015_08_12_NICU/ass_right_shank_iam_7a73fe91.stl" scale="0.001 0.001 0.001"/>
			</geometry>
			<origin rpy="0 0 0" xyz="-0.0049 -0.056 -0.081799"/>
			<material name="ass_right_shank:11_color">
				<color rgba="0.74902 0.74902 0.74902 1"/>
			</material>
		</visual>
		<collision>
			<geometry>
				<mesh filename="package://iris_sandbox//2015_08_12_NICU/ass_right_shank_iam_7a73fe91.stl" scale="0.001 0.001 0.001"/>
			</geometry>
			<origin rpy="0 0 0" xyz="-0.0049 -0.056 -0.081799"/>
		</collision>
		<inertial>
			<mass value="0.084704"/>
			<inertia ixx="0.000448" ixy="0" ixz="0.000025" iyy="0.000404" iyz="0" izz="0.000078"/>
			<origin rpy="0 0 0" xyz="0.015999 -0.026 -0.104866"/>
		</inertial>
	</link>
	<joint name="right_knee" type="revolute">
		<parent link="ass_right_thigh:11"/>
		<child link="ass_right_shank:11"/>
		<origin rpy="0 0.278258 0" xyz="-0.048258 0.0001 -0.214642"/>
		<axis xyz="0 1 0"/>
		<limit effort="30" lower="-1.29154" upper="1.53589" velocity="1"/>
	</joint>
	<link name="ass_right_ankle:11">
		<visual>
			<geometry>
				<mesh filename="package://iris_sandbox//2015_08_12_NICU/ass_right_ankle_iam_f4f7d16a.stl" scale="0.001 0.001 0.001"/>
			</geometry>
			<origin rpy="0 0 0" xyz="-0.0661 0.0031 -0.011201"/>
			<material name="ass_right_ankle:11_color">
				<color rgba="0.74902 0.74902 0.74902 1"/>
			</material>
		</visual>
		<collision>
			<geometry>
				<mesh filename="package://iris_sandbox//2015_08_12_NICU/ass_right_ankle_iam_f4f7d16a.stl" scale="0.001 0.001 0.001"/>
			</geometry>
			<origin rpy="0 0 0" xyz="-0.0661 0.0031 -0.011201"/>
		</collision>
		<inertial>
			<mass value="0.178341"/>
			<inertia ixx="0.000077" ixy="0.000001" ixz="-0.000001" iyy="0.000157" iyz="-0.000001" izz="0.00013"/>
			<origin rpy="0 0 0" xyz="-0.02173 0.025873 0.015465"/>
		</inertial>
	</link>
	<joint name="right_foot_up" type="revolute">
		<parent link="ass_right_shank:11"/>
		<child link="ass_right_ankle:11"/>
		<origin rpy="0 -0.000568 0" xyz="0.03924 -0.052 -0.216472"/>
		<axis xyz="0 1 0"/>
		<limit effort="30" lower="-0.785398" upper="0.785398" velocity="1"/>
	</joint>
	<link name="ass_right_foot:11">
		<visual>
			<geometry>
				<mesh filename="package://iris_sandbox//2015_08_12_NICU/ass_right_foot_iam_3ff7356a.stl" scale="0.001 0.001 0.001"/>
			</geometry>
			<origin rpy="0 0 0" xyz="-0.004 -0.024 -0.009365"/>
			<material name="ass_right_foot:11_color">
				<color rgba="0.74902 0.74902 0.74902 1"/>
			</material>
		</visual>
		<collision>
			<geometry>
				<mesh filename="package://iris_sandbox//2015_08_12_NICU/ass_right_foot_iam_3ff7356a.stl" scale="0.001 0.001 0.001"/>
			</geometry>
			<origin rpy="0 0 0" xyz="-0.004 -0.024 -0.009365"/>
		</collision>
		<inertial>
			<mass value="0.072801"/>
			<inertia ixx="0.000097" ixy="0.000003" ixz="-0.000001" iyy="0.000283" iyz="-0.000003" izz="0.000362"/>
			<origin rpy="0 0 0" xyz="0.074125 -0.00893 -0.031819"/>
		</inertial>
	</link>
	<joint name="right_foot" type="revolute">
		<parent link="ass_right_ankle:11"/>
		<child link="ass_right_foot:11"/>
		<origin rpy="0.046606 0 0" xyz="-0.0709 0.0261 0"/>
		<axis xyz="1 0 0"/>
		<limit effort="30" lower="-0.785398" upper="0.785398" velocity="1"/>
	</joint>
	<link name="ass_left_hip_up_MIR:11">
		<visual>
			<geometry>
				<mesh filename="package://iris_sandbox//2015_08_12_NICU/ass_right_hip_up_mir_iam_386ac7b2.stl" scale="0.001 0.001 0.001"/>
			</geometry>
			<origin rpy="0 0 0" xyz="-0.05 -0.018 -0.0007"/>
			<material name="ass_left_hip_up_MIR:11_color">
				<color rgba="0.74902 0.74902 0.74902 1"/>
			</material>
		</visual>
		<collision>
			<geometry>
				<mesh filename="package://iris_sandbox//2015_08_12_NICU/ass_right_hip_up_mir_iam_386ac7b2.stl" scale="0.001 0.001 0.001"/>
			</geometry>
			<origin rpy="0 0 0" xyz="-0.05 -0.018 -0.0007"/>
		</collision>
		<inertial>
			<mass value="0.073394"/>
			<inertia ixx="0.000029" ixy="0" ixz="0.00001" iyy="0.000118" iyz="-0" izz="0.000109"/>
			<origin rpy="0 0 0" xyz="0.004972 -0.000001 -0.01248"/>
		</inertial>
	</link>
	<joint name="left_hip_up_z" type="revolute">
		<parent link="ass_torso:11"/>
		<child link="ass_left_hip_up_MIR:11"/>
		<origin rpy="0 0 0.008271" xyz="0.010783 0.054788 0.519208"/>
		<axis xyz="0 0 1"/>
		<limit effort="30" lower="-0.698132" upper="1.134464" velocity="1"/>
	</joint>
	<link name="ass_left_hip_low_MIR:11">
		<visual>
			<geometry>
				<mesh filename="package://iris_sandbox//2015_08_12_NICU/ass_right_hip_up2_mir_iam_b8a74a0a.stl" scale="0.001 0.001 0.001"/>
			</geometry>
			<origin rpy="0 0 0" xyz="0.0031 -0.023 -0.025201"/>
			<material name="ass_left_hip_low_MIR:11_color">
				<color rgba="0.74902 0.74902 0.74902 1"/>
			</material>
		</visual>
		<collision>
			<geometry>
				<mesh filename="package://iris_sandbox//2015_08_12_NICU/ass_right_hip_up2_mir_iam_b8a74a0a.stl" scale="0.001 0.001 0.001"/>
			</geometry>
			<origin rpy="0 0 0" xyz="0.0031 -0.023 -0.025201"/>
		</collision>
		<inertial>
			<mass value="0.17834"/>
			<inertia ixx="0.000077" ixy="-0.000001" ixz="0.000001" iyy="0.000157" iyz="-0.000001" izz="0.00013"/>
			<origin rpy="0 0 0" xyz="0.04747 0.00023 -0.015465"/>
		</inertial>
	</link>
	<joint name="left_hip_up_x" type="revolute">
		<parent link="ass_left_hip_up_MIR:11"/>
		<child link="ass_left_hip_low_MIR:11"/>
		<origin rpy="0.000434 0 0" xyz="-0.046 0 -0.0414"/>
		<axis xyz="1 0 0"/>
		<limit effort="30" lower="-0.418879" upper="1.22173" velocity="1"/>
	</joint>
	<link name="ass_left_thigh:11">
		<visual>
			<geometry>
				<mesh filename="package://iris_sandbox//2015_08_12_NICU/ass_thigh_left_complete_iam_5a6ba909.stl" scale="0.001 0.001 0.001"/>
			</geometry>
			<origin rpy="0 0 0" xyz="-0.04583 -0.056 -0.100647"/>
			<material name="ass_left_thigh:11_color">
				<color rgba="0.74902 0.74902 0.74902 1"/>
			</material>
		</visual>
		<collision>
			<geometry>
				<mesh filename="package://iris_sandbox//2015_08_12_NICU/ass_thigh_left_complete_iam_5a6ba909.stl" scale="0.001 0.001 0.001"/>
			</geometry>
			<origin rpy="0 0 0" xyz="-0.04583 -0.056 -0.100647"/>
		</collision>
		<inertial>
			<mass value="0.177251"/>
			<inertia ixx="0.000918" ixy="0.000001" ixz="-0.000093" iyy="0.000883" iyz="0.000003" izz="0.000125"/>
			<origin rpy="0 0 0" xyz="-0.029925 -0.02577 -0.151365"/>
		</inertial>
	</link>
	<joint name="left_hip_up_y" type="revolute">
		<parent link="ass_left_hip_low_MIR:11"/>
		<child link="ass_left_thigh:11"/>
		<origin rpy="0 -0.329409 0" xyz="0.0692 0.0261 -0"/>
		<axis xyz="0 1 0"/>
		<limit effort="30" lower="-1.57" upper="0.698132" velocity="1"/>
	</joint>
	<link name="ass_left_shank_MIR:11">
		<visual>
			<geometry>
				<mesh filename="package://iris_sandbox//2015_08_12_NICU/ass_right_shank_mir_iam_a2a9b5d0.stl" scale="0.001 0.001 0.001"/>
			</geometry>
			<origin rpy="0 0 0" xyz="-0.004901 -0.056 -0.03453"/>
			<material name="ass_left_shank_MIR:11_color">
				<color rgba="0.74902 0.74902 0.74902 1"/>
			</material>
		</visual>
		<collision>
			<geometry>
				<mesh filename="package://iris_sandbox//2015_08_12_NICU/ass_right_shank_mir_iam_a2a9b5d0.stl" scale="0.001 0.001 0.001"/>
			</geometry>
			<origin rpy="0 0 0" xyz="-0.004901 -0.056 -0.03453"/>
		</collision>
		<inertial>
			<mass value="0.084704"/>
			<inertia ixx="0.000448" ixy="0" ixz="0.000025" iyy="0.000404" iyz="0" izz="0.000078"/>
			<origin rpy="0 0 0" xyz="0.015999 -0.026 -0.104865"/>
		</inertial>
	</link>
	<joint name="left_knee" type="revolute">
		<parent link="ass_left_thigh:11"/>
		<child link="ass_left_shank_MIR:11"/>
		<origin rpy="0 0.495699 0" xyz="-0.048258 0.0001 -0.214642"/>
		<axis xyz="-0.00827124 0.999966 0.000434192"/>
		<limit effort="30" lower="-1.29154" upper="1.53589" velocity="1"/>
	</joint>
	<link name="ass_left_ankle_MIR:11">
		<visual>
			<geometry>
				<mesh filename="package://iris_sandbox//2015_08_12_NICU/ass_right_ankle_mir_iam_c5a384f4.stl" scale="0.001 0.001 0.001"/>
			</geometry>
			<origin rpy="0 0 0" xyz="-0.0661 -0.0491 0.025201"/>
			<material name="ass_left_ankle_MIR:11_color">
				<color rgba="0.74902 0.74902 0.74902 1"/>
			</material>
		</visual>
		<collision>
			<geometry>
				<mesh filename="package://iris_sandbox//2015_08_12_NICU/ass_right_ankle_mir_iam_c5a384f4.stl" scale="0.001 0.001 0.001"/>
			</geometry>
			<origin rpy="0 0 0" xyz="-0.0661 -0.0491 0.025201"/>
		</collision>
		<inertial>
			<mass value="0.17834"/>
			<inertia ixx="0.000077" ixy="-0.000001" ixz="-0.000001" iyy="0.000157" iyz="0.000001" izz="0.00013"/>
			<origin rpy="0 0 0" xyz="-0.02173 -0.025873 0.015465"/>
		</inertial>
	</link>
	<joint name="left_foot_up" type="revolute">
		<parent link="ass_left_shank_MIR:11"/>
		<child link="ass_left_ankle_MIR:11"/>
		<origin rpy="0 -0.120898 0" xyz="0.03924 0 -0.216472"/>
		<axis xyz="0 1 0"/>
		<limit effort="30" lower="-0.785398" upper="0.785398" velocity="1"/>
	</joint>
	<link name="ass_left_foot:11">
		<visual>
			<geometry>
				<mesh filename="package://iris_sandbox//2015_08_12_NICU/ass_left_foot_iam_620666ef.stl" scale="0.001 0.001 0.001"/>
			</geometry>
			<origin rpy="0 0 0" xyz="-0.004 -0.024 -0.033621"/>
			<material name="ass_left_foot:11_color">
				<color rgba="0.74902 0.74902 0.74902 1"/>
			</material>
		</visual>
		<collision>
			<geometry>
				<mesh filename="package://iris_sandbox//2015_08_12_NICU/ass_left_foot_iam_620666ef.stl" scale="0.001 0.001 0.001"/>
			</geometry>
			<origin rpy="0 0 0" xyz="-0.004 -0.024 -0.033621"/>
		</collision>
		<inertial>
			<mass value="0.072801"/>
			<inertia ixx="0.000097" ixy="-0.000003" ixz="-0.000001" iyy="0.000283" iyz="0.000003" izz="0.000362"/>
			<origin rpy="0 0 0" xyz="0.074087 0.008929 -0.031819"/>
		</inertial>
	</link>
	<joint name="left_foot" type="revolute">
		<parent link="ass_left_ankle_MIR:11"/>
		<child link="ass_left_foot:11"/>
		<origin rpy="0.011381 0 0" xyz="-0.0709 -0.0261 0"/>
		<axis xyz="1 0 0"/>
		<limit effort="30" lower="-0.785398" upper="0.785398" velocity="1"/>
	</joint>
	<link name="ass_left_shoulder:11">
		<visual>
			<geometry>
				<mesh filename="package://iris_sandbox//2015_08_12_NICU/ass_left_shoulder_iam_1ca4d925.stl" scale="0.001 0.001 0.001"/>
			</geometry>
			<origin rpy="0 0 0" xyz="0.022045 0.022577 0.037082"/>
			<material name="ass_left_shoulder:11_color">
				<color rgba="0.74902 0.74902 0.74902 1"/>
			</material>
		</visual>
		<collision>
			<geometry>
				<mesh filename="package://iris_sandbox//2015_08_12_NICU/ass_left_shoulder_iam_1ca4d925.stl" scale="0.001 0.001 0.001"/>
			</geometry>
			<origin rpy="0 0 0" xyz="0.022045 0.022577 0.037082"/>
		</collision>
		<inertial>
			<mass value="0.084038"/>
			<inertia ixx="0.000026" ixy="-0.000001" ixz="-0.000002" iyy="0.000034" iyz="-0" izz="0.000033"/>
			<origin rpy="0 0 0" xyz="0.0057 0.000259 0.033153"/>
		</inertial>
	</link>
	<joint name="left_shoulder" type="revolute">
		<parent link="ass_torso:11"/>
		<child link="ass_left_shoulder:11"/>
		<origin rpy="0 0 -0.008349" xyz="0.026868 0.04375 0.749809"/>
		<axis xyz="0 0 1"/>
		<limit effort="30" lower="-0.663225" upper="2.44346" velocity="1"/>
	</joint>
	<link name="ass_left_upper_arm:11">
		<visual>
			<geometry>
				<mesh filename="package://iris_sandbox//2015_08_12_NICU/ass_left_upper_arm_iam_49d50008.stl" scale="0.001 0.001 0.001"/>
			</geometry>
			<origin rpy="0 0 0" xyz="-0.00032 -0.000277 0.000298"/>
			<material name="ass_left_upper_arm:11_color">
				<color rgba="0.74902 0.74902 0.74902 1"/>
			</material>
		</visual>
		<collision>
			<geometry>
				<mesh filename="package://iris_sandbox//2015_08_12_NICU/ass_left_upper_arm_iam_49d50008.stl" scale="0.001 0.001 0.001"/>
			</geometry>
			<origin rpy="0 0 0" xyz="-0.00032 -0.000277 0.000298"/>
		</collision>
		<inertial>
			<mass value="0.024811"/>
			<inertia ixx="0.000014" ixy="0" ixz="0" iyy="0.000011" iyz="0.000001" izz="0.000019"/>
			<origin rpy="0 0 0" xyz="-0 0.041345 -0.002364"/>
		</inertial>
	</link>
	<joint name="left_shoulder_upper_arm" type="revolute">
		<parent link="ass_left_shoulder:11"/>
		<child link="ass_left_upper_arm:11"/>
		<origin rpy="0 0.040448 -0.006359" xyz="0.022149 0.023361 0.037"/>
		<axis xyz="0 1 0"/>
		<limit effort="30" lower="-1.22173" upper="0.942478" velocity="1"/>
	</joint>
	<link name="ass_left_lower_arm:11">
		<visual>
			<geometry>
				<mesh filename="package://iris_sandbox//2015_08_12_NICU/ass_left_lower_arm_iam_5be2a521.stl" scale="0.001 0.001 0.001"/>
			</geometry>
			<origin rpy="0 0 0" xyz="-0.046901 -0.022899 -0.171171"/>
			<material name="ass_left_lower_arm:11_color">
				<color rgba="0.74902 0.74902 0.74902 1"/>
			</material>
		</visual>
		<collision>
			<geometry>
				<mesh filename="package://iris_sandbox//2015_08_12_NICU/ass_left_lower_arm_iam_5be2a521.stl" scale="0.001 0.001 0.001"/>
			</geometry>
			<origin rpy="0 0 0" xyz="-0.046901 -0.022899 -0.171171"/>
		</collision>
		<inertial>
			<mass value="0.192147"/>
			<inertia ixx="0.00087" ixy="0" ixz="-0.000003" iyy="0.00087" iyz="0.000003" izz="0.000049"/>
			<origin rpy="0 0 0" xyz="-0.02382 0.000181 -0.0866"/>
		</inertial>
	</link>
	<joint name="left_upper_arm" type="revolute">
		<parent link="ass_left_upper_arm:11"/>
		<child link="ass_left_lower_arm:11"/>
		<origin rpy="-0.003683 0 0" xyz="0.0245 0.073664 -0.022853"/>
		<axis xyz="1 0 0"/>
		<limit effort="30" lower="-3.124139" upper="3.124139" velocity="1"/>
	</joint>
	<link name="ass_left_wrist_MIR:11">
		<visual>
			<geometry>
				<mesh filename="package://iris_sandbox//2015_08_12_NICU/ass_right_wrist_mir_iam_dcfe6de3.stl" scale="0.001 0.001 0.001"/>
			</geometry>
			<origin rpy="0 0 0" xyz="0.000017 -0.010774 -0.12546"/>
			<material name="ass_left_wrist_MIR:11_color">
				<color rgba="0.74902 0.74902 0.74902 1"/>
			</material>
		</visual>
		<collision>
			<geometry>
				<mesh filename="package://iris_sandbox//2015_08_12_NICU/ass_right_wrist_mir_iam_dcfe6de3.stl" scale="0.001 0.001 0.001"/>
			</geometry>
			<origin rpy="0 0 0" xyz="0.000017 -0.010774 -0.12546"/>
		</collision>
		<inertial>
			<mass value="0.076791"/>
			<inertia ixx="0.000104" ixy="-0" ixz="-0" iyy="0.000095" iyz="0.000002" izz="0.000021"/>
			<origin rpy="0 0 0" xyz="0 -0.022485 -0.081055"/>
		</inertial>
	</link>
	<joint name="left_lower_arm" type="revolute">
		<parent link="ass_left_lower_arm:11"/>
		<child link="ass_left_wrist_MIR:11"/>
		<origin rpy="0 -0.006197 0" xyz="-0.024001 0.024001 -0.1732"/>
		<axis xyz="0 1 0"/>
		<limit effort="30" lower="-0.174533" upper="1.4835" velocity="1"/>
	</joint>
	<link name="ass_left_gripper_MIR:11">
		<visual>
			<geometry>
				<mesh filename="package://iris_sandbox//2015_08_12_NICU/ass_right_gripper_mir_iam_56fa54a4.stl" scale="0.001 0.001 0.001"/>
			</geometry>
			<origin rpy="0 0 0" xyz="-0.01775 -0.0427 -0.032125"/>
			<material name="ass_left_gripper_MIR:11_color">
				<color rgba="0.74902 0.74902 0.74902 1"/>
			</material>
		</visual>
		<collision>
			<geometry>
				<mesh filename="package://iris_sandbox//2015_08_12_NICU/ass_right_gripper_mir_iam_56fa54a4.stl" scale="0.001 0.001 0.001"/>
			</geometry>
			<origin rpy="0 0 0" xyz="-0.01775 -0.0427 -0.032125"/>
		</collision>
		<inertial>
			<mass value="0.05064"/>
			<inertia ixx="0.000021" ixy="-0" ixz="-0" iyy="0.000015" iyz="-0.000004" izz="0.000018"/>
			<origin rpy="0 0 0" xyz="0.000282 -0.013872 -0.023149"/>
		</inertial>
	</link>
	<joint name="left_wrist" type="revolute">
		<parent link="ass_left_wrist_MIR:11"/>
		<child link="ass_left_gripper_MIR:11"/>
		<origin rpy="0 0 0.010808" xyz="0 -0.010199 -0.12575"/>
		<axis xyz="0 0 1"/>
		<limit effort="30" lower="-3.124139" upper="3.124139" velocity="1"/>
	</joint>
	<link name="ass_left_gripper_move:11">
		<visual>
			<geometry>
				<mesh filename="package://iris_sandbox//2015_08_12_NICU/ass_left_gripper_move_iam_24ff33ee.stl" scale="0.001 0.001 0.001"/>
			</geometry>
			<origin rpy="0 0 0" xyz="-0.042126 0.000717 -0.000317"/>
			<material name="ass_left_gripper_move:11_color">
				<color rgba="0.74902 0.74902 0.74902 1"/>
			</material>
		</visual>
		<collision>
			<geometry>
				<mesh filename="package://iris_sandbox//2015_08_12_NICU/ass_left_gripper_move_iam_24ff33ee.stl" scale="0.001 0.001 0.001"/>
			</geometry>
			<origin rpy="0 0 0" xyz="-0.042126 0.000717 -0.000317"/>
		</collision>
		<inertial>
			<mass value="0.008515"/>
			<inertia ixx="0.000007" ixy="0" ixz="0" iyy="0.000009" iyz="-0.000002" izz="0.000004"/>
			<origin rpy="0 0 0" xyz="-0.0205 0.006926 -0.037561"/>
		</inertial>
	</link>
	<joint name="left_gripper" type="revolute">
		<parent link="ass_left_gripper_MIR:11"/>
		<child link="ass_left_gripper_move:11"/>
		<origin rpy="-0.061565 0 0" xyz="0.02075 0 -0.020999"/>
		<axis xyz="0.999405 -0.00386806 -0.0342822"/>
		<limit effort="30" lower="-0.837758" upper="0.610865" velocity="1"/>
	</joint>
</robot>

