<robot name="testbot">

<gazebo>
  <plugin name="gazebo_ros_control" filename="libgazebo_ros_control.so">
    <robotNamespace>/testbot</robotNamespace>
  </plugin>
</gazebo>

<!-- Links -->	
	<link name="world"/> <!-- Used for fixing robot to Gazebo 'base_link' -->

	<link name="base_link">
		<visual>
			<origin xyz="0 0 0.01" rpy="0 0 0"/>
			<geometry>
				<box size="0.2 0.2 0.01"/>
			</geometry>
			<material name="black">
				<color rgba="0.0 0.0 0.0 1.0"/>
			</material>
		</visual>
		<collision>
			<origin xyz="0 0 0.01" rpy="0 0 0"/>
			<geometry>
				<box size="0.2 0.2 0.01"/>
			</geometry>
		</collision>
		<inertial>
			<origin xyz="0 0 0.01" rpy="0 0 0"/>
			<mass value ="1"/>
			<inertia 
				ixx="1.0" ixy="0.0" ixz="0.0"
				iyy="1.0" iyz="0.0"
				izz="1.0"/>
		</inertial>
	</link>
	<gazebo reference="base_link">
		<material>Gazebo/DarkGrey</material>
	</gazebo>

	<link name="base_cyl">
		<visual>
			<origin xyz="0 0 0.0" rpy="0 0 0"/>
			<geometry>
				<cylinder radius="0.05" length="0.1"/>
			</geometry>
			<material name="white">
				<color rgba="1.0 1.0 1.0 1.0"/>
			</material>
		</visual>
		<collision>
			<origin xyz="0 0 0.0" rpy="0 0 0"/>
			<geometry>
				<cylinder radius="0.05" length="0.1"/>
			</geometry>
		</collision>
		<inertial>
			<origin xyz="0 0 0" rpy="0 0 0"/>
			<mass value ="1"/>
			<inertia 
				ixx="1.0" ixy="0.0" ixz="0.0"
				iyy="1.0" iyz="0.0"
				izz="1.0"/>
		</inertial>
	</link>
	<gazebo reference="base_cyl">
		<material>Gazebo/DarkGrey</material>
	</gazebo>

	<link name="first_link_cyl">
		<visual>
			<origin xyz="0 0 0.0" rpy="1.57079632679 0 0"/>
			<geometry>
				<cylinder radius="0.05" length="0.1"/>
			</geometry>
			<material name="red">
				<color rgba="1.0 0.0 0.0 1.0"/>
			</material>
		</visual>
		<collision>
			<origin xyz="0 0 0.0" rpy="1.57079632679 0 0"/>
			<geometry>
				<cylinder radius="0.05" length="0.1"/>
			</geometry>
		</collision>
		<inertial>
			<origin xyz="0 0 0" rpy="1.57079632679 0 0"/>
			<mass value ="1"/>
			<inertia 
				ixx="1.0" ixy="0.0" ixz="0.0"
				iyy="1.0" iyz="0.0"
				izz="1.0"/>
		</inertial>
	</link>
	<gazebo reference="first_link_cyl">
		<material>Gazebo/Red</material>
	</gazebo>

	<link name="first_link_stick">
		<visual>
			<origin xyz="0 0 0" rpy="0 0 0"/>
			<geometry>
				<box size="0.2 0.1 0.1"/>
			</geometry>
			<material name="red"/>
		</visual>
		<collision>
			<origin xyz="0 0 0" rpy="0 0 0"/>
			<geometry>
				<box size="0.2 0.1 0.1"/>
			</geometry>
		</collision>
		<inertial>
			<origin xyz="0 0 0" rpy="0 0 0"/>
			<mass value ="1"/>
			<inertia 
				ixx="1.0" ixy="0.0" ixz="0.0"
				iyy="1.0" iyz="0.0"
				izz="1.0"/>
		</inertial>
	</link>
	<gazebo reference="first_link_stick">
		<material>Gazebo/Red</material>
	</gazebo>

	<link name="second_link_cyl">
		<visual>
			<origin xyz="0 0 0" rpy="1.57079632679 0 0"/>
			<geometry>
				<cylinder radius="0.05" length="0.1"/>
			</geometry>
			<material name="green">
				<color rgba="0.0 1.0 0.0 1.0"/>
			</material>
		</visual>
		<collision>
			<origin xyz="0 0 0" rpy="1.57079632679 0 0"/>
			<geometry>
				<cylinder radius="0.05" length="0.1"/>
			</geometry>
		</collision>
		<inertial>
			<origin xyz="0 0 0" rpy="1.57079632679 0 0"/>
			<mass value ="1"/>
			<inertia 
				ixx="1.0" ixy="0.0" ixz="0.0"
				iyy="1.0" iyz="0.0"
				izz="1.0"/>
		</inertial>
	</link>
	<gazebo reference="second_link_cyl">
		<material>Gazebo/Green</material>
	</gazebo>

	<link name="second_link_stick">
		<visual>
			<origin xyz="0 0 0" rpy="0 0 0"/>
			<geometry>
				<box size="0.2 0.1 0.1"/>
			</geometry>
			<material name="green"/>
		</visual>
		<collision>
			<origin xyz="0 0 0" rpy="0 0 0"/>
			<geometry>
				<box size="0.2 0.1 0.1"/>
			</geometry>
		</collision>
		<inertial>
			<origin xyz="0 0 0" rpy="0 0 0"/>
			<mass value ="1"/>
			<inertia 
				ixx="1.0" ixy="0.0" ixz="0.0"
				iyy="1.0" iyz="0.0"
				izz="1.0"/>
		</inertial>
	</link>
	<gazebo reference="second_link_stick">
		<material>Gazebo/Green</material>
	</gazebo>

	<link name="third_link_cyl">
		<visual>
			<origin xyz="0 0 0" rpy="1.57079632679 0 0"/>
			<geometry>
				<cylinder radius="0.05" length="0.1"/>
 
			</geometry>
			<material name="blue">
				<color rgba="0.0 0.0 1.0 1.0"/>
			</material>
		</visual>
		<collision>
			<origin xyz="0 0 0" rpy="1.57079632679 0 0"/>
			<geometry>
				<cylinder radius="0.05" length="0.1"/>
 
			</geometry>
		</collision>
		<inertial>
			<origin xyz="0 0 0" rpy="1.57079632679 0 0"/>
			<mass value ="1"/>
			<inertia 
				ixx="1.0" ixy="0.0" ixz="0.0"
				iyy="1.0" iyz="0.0"
				izz="1.0"/>
		</inertial>
	</link>
	<gazebo reference="third_link_cyl">
		<material>Gazebo/Blue</material>
	</gazebo>

	<link name="third_link_stick">
		<visual>
			<origin xyz="0 0 0" rpy="0 0 0"/>
			<geometry>
				<box size="0.2 0.1 0.1"/>
			</geometry>
			<material name="blue"/>
		</visual>
		<collision>
			<origin xyz="0 0 0" rpy="0 0 0"/>
			<geometry>
				<box size="0.2 0.1 0.1"/>
			</geometry>
		</collision>
		<inertial>
			<origin xyz="0 0 0" rpy="0 0 0"/>
			<mass value ="1"/>
			<inertia 
				ixx="1.0" ixy="0.0" ixz="0.0"
				iyy="1.0" iyz="0.0"
				izz="1.0"/>
		</inertial>
	</link>
	<gazebo reference="third_link_stick">
		<material>Gazebo/Blue</material>
	</gazebo>

	<link name="tcp">
		<visual>
			<origin xyz="0 0 0" rpy="0 1.57079632679 0"/>
			<geometry>
				<box size="0.05 0.05 0.05"/>
			</geometry>
			<material name="gray">
				<color rgba="0.5 0.5 0.5 1.0"/>
			</material>
		</visual>
		<collision>
			<origin xyz="0 0 0" rpy="0 1.57079632679 0"/>
			<geometry>
				<box size="0.05 0.05 0.05"/>
			</geometry>
		</collision>
		<inertial>
			<origin xyz="0 0 0" rpy="0 1.57079632679 0"/>
			<mass value ="1"/>
			<inertia 
				ixx="1.0" ixy="0.0" ixz="0.0"
				iyy="1.0" iyz="0.0"
				izz="1.0"/>
		</inertial>
	</link>
	<gazebo reference="tcp">
		<material>Gazebo/Orange</material>
	</gazebo>

<!-- Fixed -->
	<joint name="fixed" type="fixed">
		<parent link="world"/>
		<child link="base_link"/>
	</joint>

	<joint name="first_cyl_to_stick" type="fixed">
		<parent link="first_link_cyl"/>
		<child link="first_link_stick"/>
		<origin xyz="0.15 0 0"/>
	</joint>
	<joint name="second_cyl_to_stick" type="fixed">
		<parent link="second_link_cyl"/>
		<child link="second_link_stick"/>
		<origin xyz="0.15 0 0"/>
	</joint>
	<joint name="third_cyl_to_stick" type="fixed">
		<parent link="third_link_cyl"/>
		<child link="third_link_stick"/>
		<origin xyz="0.15 0 0"/>
	</joint>
	<joint name="tcp" type="fixed">
		<parent link="third_link_stick"/>
		<child link="tcp"/>
		<origin xyz="0.125 0 0"/>
	</joint>

<!-- Movables -->
	<joint name="base_joint" type="continuous">
		<parent link="base_link"/>
		<child link="base_cyl"/>
		<origin xyz="0 0 0.07"/>
		<axis xyz="0 0 1"/>
		<!--<limit effort="1" velocity="1.57079632679" lower="-3.14159265359" upper="3.14159265359" /> -->
	</joint>
	<joint name="first_joint" type="continuous">
		<parent link="base_cyl"/>
		<child link="first_link_cyl"/>
		<origin xyz="0 0 0.1"/>
		<axis xyz="0 1 0"/>
		<!--<limit effort="1" velocity="1.57079632679" lower="-3.14159265359" upper="3.14159265359" /> -->
	</joint>
	<joint name="second_joint" type="continuous">
		<parent link="first_link_stick"/>
		<child link="second_link_cyl"/>
		<origin xyz="0.15 0 0"/>
		<axis xyz="0 1 0"/>
		<!--<limit effort="1" velocity="1.57079632679" lower="-3.14159265359" upper="3.14159265359" /> -->
	</joint>
	<joint name="third_joint" type="continuous">
		<parent link="second_link_stick"/>
		<child link="third_link_cyl"/>
		<origin xyz="0.15 0 0"/>
		<axis xyz="0 1 0"/>
		<!--<limit effort="1" velocity="1.57079632679" lower="-3.14159265359" upper="3.14159265359" /> -->
	</joint>

<!-- Transmissions -->
  <transmission name="tran0">
    <type>transmission_interface/SimpleTransmission</type>
    <joint name="base_joint">
      <hardwareInterface>EffortJointInterface</hardwareInterface>
    </joint>
    <actuator name="motor0">
      <hardwareInterface>EffortJointInterface</hardwareInterface>
      <mechanicalReduction>1</mechanicalReduction>
    </actuator>
  </transmission>

  <transmission name="tran1">
    <type>transmission_interface/SimpleTransmission</type>
    <joint name="first_joint">
      <hardwareInterface>EffortJointInterface</hardwareInterface>
    </joint>
    <actuator name="motor1">
      <hardwareInterface>EffortJointInterface</hardwareInterface>
      <mechanicalReduction>1</mechanicalReduction>
    </actuator>
  </transmission>

  <transmission name="tran2">
    <type>transmission_interface/SimpleTransmission</type>
    <joint name="second_joint">
      <hardwareInterface>EffortJointInterface</hardwareInterface>
    </joint>
    <actuator name="motor2">
      <hardwareInterface>EffortJointInterface</hardwareInterface>
      <mechanicalReduction>1</mechanicalReduction>
    </actuator>
  </transmission>

 <transmission name="tran3">
    <type>transmission_interface/SimpleTransmission</type>
    <joint name="third_joint">
      <hardwareInterface>EffortJointInterface</hardwareInterface>
    </joint>
    <actuator name="motor3">
      <hardwareInterface>EffortJointInterface</hardwareInterface>
      <mechanicalReduction>1</mechanicalReduction>
    </actuator>
  </transmission>


</robot>
