<robot name="testbot">

<!-- Links -->
	<link name="world"/>

	<link name="base_link">
		<visual>
			<origin xyz="0 0 0.01" rpy="0 0 0"/>
			<geometry>
				<box size="0.2 0.2 0.01"/>
			</geometry>
			<material name="black">
				<color rgba="0.0 0.0 0.0 1.0"/>
			</material>
		</visual>
	</link>

	<link name="base_cyl">
		<visual>
			<origin xyz="0 0 0.0" rpy="0 0 0"/>
			<geometry>
				<cylinder radius="0.05" length="0.1"/>
			</geometry>
			<material name="white">
				<color rgba="1.0 1.0 1.0 1.0"/>
			</material>
		</visual>
	</link>

	<link name="first_link_cyl">
		<visual>
			<origin xyz="0 0 0.0" rpy="1.57079632679 0 0"/>
			<geometry>
				<cylinder radius="0.05" length="0.1"/>
			</geometry>
			<material name="red">
				<color rgba="1.0 0.0 0.0 1.0"/>
			</material>
		</visual>
	</link>

	<link name="first_link_stick">
		<visual>
			<origin xyz="0 0 0" rpy="0 0 0"/>
			<geometry>
				<box size="0.2 0.1 0.1"/>
			</geometry>
			<material name="red"/>
		</visual>
	</link>

	<link name="second_link_cyl">
		<visual>
			<origin xyz="0 0 0" rpy="1.57079632679 0 0"/>
			<geometry>
				<cylinder radius="0.05" length="0.1"/>
			</geometry>
			<material name="green">
				<color rgba="0.0 1.0 0.0 1.0"/>
			</material>
		</visual>
	</link>

	<link name="second_link_stick">
		<visual>
			<origin xyz="0 0 0" rpy="0 0 0"/>
			<geometry>
				<box size="0.2 0.1 0.1"/>
			</geometry>
			<material name="green"/>
		</visual>
	</link>

	<link name="third_link_cyl">
		<visual>
			<origin xyz="0 0 0" rpy="1.57079632679 0 0"/>
			<geometry>
				<cylinder radius="0.05" length="0.1"/>
 
			</geometry>
			<material name="blue">
				<color rgba="0.0 0.0 1.0 1.0"/>
			</material>
		</visual>
	</link>

	<link name="third_link_stick">
		<visual>
			<origin xyz="0 0 0" rpy="0 0 0"/>
			<geometry>
				<box size="0.2 0.1 0.1"/>
			</geometry>
			<material name="blue"/>
		</visual>
	</link>

	<link name="tcp">
		<visual>
			<origin xyz="0 0 0" rpy="0 1.57079632679 0"/>
			<geometry>
				<box size="0.05 0.05 0.05"/>
			</geometry>
			<material name="gray">
				<color rgba="0.5 0.5 0.5 1.0"/>
			</material>
		</visual>
	</link>

<!-- Fixed -->
	<joint name="fixed" type="fixed">
		<parent link="world"/>
		<child link="base_link"/>
	</joint>

	<joint name="first_cyl_to_stick" type="fixed">
		<parent link="first_link_cyl"/>
		<child link="first_link_stick"/>
		<origin xyz="0.15 0 0"/>
	</joint>
	<joint name="second_cyl_to_stick" type="fixed">
		<parent link="second_link_cyl"/>
		<child link="second_link_stick"/>
		<origin xyz="0.15 0 0"/>
	</joint>
	<joint name="third_cyl_to_stick" type="fixed">
		<parent link="third_link_cyl"/>
		<child link="third_link_stick"/>
		<origin xyz="0.15 0 0"/>
	</joint>
	<joint name="tcp" type="fixed">
		<parent link="third_link_stick"/>
		<child link="tcp"/>
		<origin xyz="0.125 0 0"/>
	</joint>

<!-- Movables -->
	<joint name="base_joint" type="continuous">
		<parent link="base_link"/>
		<child link="base_cyl"/>
		<origin xyz="0 0 0.07"/>
		<axis xyz="0 0 1"/>
	</joint>
	<joint name="first_joint" type="continuous">
		<parent link="base_cyl"/>
		<child link="first_link_cyl"/>
		<origin xyz="0 0 0.1"/>
		<axis xyz="0 1 0"/>
	</joint>
	<joint name="second_joint" type="continuous">
		<parent link="first_link_stick"/>
		<child link="second_link_cyl"/>
		<origin xyz="0.15 0 0"/>
		<axis xyz="0 1 0"/>
	</joint>
	<joint name="third_joint" type="continuous">
		<parent link="second_link_stick"/>
		<child link="third_link_cyl"/>
		<origin xyz="0.15 0 0"/>
		<axis xyz="0 1 0"/>
	</joint>
</robot>
